{
 "cells": [
  {
   "cell_type": "code",
   "execution_count": 1,
   "id": "c2c2020a",
   "metadata": {},
   "outputs": [
    {
     "name": "stderr",
     "output_type": "stream",
     "text": [
      "/opt/conda/miniconda3/lib/python3.8/site-packages/scipy/__init__.py:138: UserWarning: A NumPy version >=1.16.5 and <1.23.0 is required for this version of SciPy (detected version 1.23.4)\n",
      "  warnings.warn(f\"A NumPy version >={np_minversion} and <{np_maxversion} is required for this version of \"\n"
     ]
    }
   ],
   "source": [
    "from pyspark.ml import Pipeline, PipelineModel\n",
    "from pyspark.ml.classification import LogisticRegression\n",
    "from pyspark.ml.feature import HashingTF, Tokenizer\n",
    "from pyspark.ml.evaluation import BinaryClassificationEvaluator\n",
    "from pyspark.sql import SparkSession\n",
    "from pyspark.ml.functions import vector_to_array\n",
    "from pyspark.sql import functions as F\n",
    "import argparse"
   ]
  },
  {
   "cell_type": "code",
   "execution_count": 2,
   "id": "e284da38",
   "metadata": {},
   "outputs": [],
   "source": [
    "table = 'reddit_table'\n",
    "model_path = '/user/bda_reddit_pw/models/sentiment_model'\n",
    "result_path = '/user/bda_reddit_pw/models/results/sentiment_results'\n",
    "day_shift = 20\n",
    "\n",
    "spark = SparkSession.builder \\\n",
    "    .master('local[1]') \\\n",
    "    .appName('Sentiment Prediction') \\\n",
    "    .enableHiveSupport() \\\n",
    "    .getOrCreate()\n",
    "\n",
    "spark.sparkContext.setLogLevel('ERROR')"
   ]
  },
  {
   "cell_type": "code",
   "execution_count": 3,
   "id": "ee2ccad5",
   "metadata": {},
   "outputs": [
    {
     "name": "stderr",
     "output_type": "stream",
     "text": [
      "                                                                                \r"
     ]
    }
   ],
   "source": [
    "loaded_model = PipelineModel.load(model_path)"
   ]
  },
  {
   "cell_type": "code",
   "execution_count": 4,
   "id": "a4eef16b",
   "metadata": {},
   "outputs": [
    {
     "name": "stderr",
     "output_type": "stream",
     "text": [
      "ivysettings.xml file not found in HIVE_HOME or HIVE_CONF_DIR,/etc/hive/conf.dist/ivysettings.xml will be used\n"
     ]
    }
   ],
   "source": [
    "test_df = spark.sql(f'SELECT * FROM {table}')"
   ]
  },
  {
   "cell_type": "code",
   "execution_count": 5,
   "id": "a7539046",
   "metadata": {},
   "outputs": [],
   "source": [
    "test_df = test_df.withColumnRenamed('selftext', 'text')"
   ]
  },
  {
   "cell_type": "code",
   "execution_count": 6,
   "id": "1b0e8141",
   "metadata": {},
   "outputs": [
    {
     "name": "stderr",
     "output_type": "stream",
     "text": [
      "\r",
      "[Stage 10:>                                                         (0 + 1) / 1]\r"
     ]
    },
    {
     "name": "stdout",
     "output_type": "stream",
     "text": [
      "+--------------------+------------+--------------+----+-----+---+----+\n",
      "|                text| created_utc|cryptocurrency|year|month|day|hour|\n",
      "+--------------------+------------+--------------+----+-----+---+----+\n",
      "|                    |1.66458368E9|        solana|2022|   10|  1|   0|\n",
      "|disclaimer long b...|1.66458483E9|       cardano|2022|   10|  1|   0|\n",
      "|bob send address ...|1.66458573E9|       bitcoin|2022|   10|  1|   0|\n",
      "|back get much res...|1.66458944E9|      dogecoin|2022|   10|  1|   1|\n",
      "|glaring lack lite...| 1.6645897E9|       bitcoin|2022|   10|  1|   2|\n",
      "|sitting wallet bl...| 1.6645952E9|       bitcoin|2022|   10|  1|   3|\n",
      "|huge advocate thi...|1.66459558E9|      ethereum|2022|   10|  1|   3|\n",
      "|know time chain w...|1.66459661E9|       bitcoin|2022|   10|  1|   3|\n",
      "|discord invite li...|1.66459686E9|           xrp|2022|   10|  1|   4|\n",
      "|      safe left know|1.66459994E9|       bitcoin|2022|   10|  1|   4|\n",
      "|please utilize st...|1.66460083E9|       bitcoin|2022|   10|  1|   5|\n",
      "|see lot people ha...|1.66460147E9|       bitcoin|2022|   10|  1|   5|\n",
      "|hello everyone we...|1.66460224E9|       cardano|2022|   10|  1|   5|\n",
      "|forenote going ch...| 1.6646135E9|       bitcoin|2022|   10|  1|   8|\n",
      "|sent address curr...|1.66461517E9|       cardano|2022|   10|  1|   9|\n",
      "|start design rich...| 1.6646153E9|       bitcoin|2022|   10|  1|   9|\n",
      "|basic understandi...|1.66461709E9|       bitcoin|2022|   10|  1|   9|\n",
      "|hello got money d...|1.66461811E9|       bitcoin|2022|   10|  1|   9|\n",
      "|retain privacy re...|1.66461926E9|       bitcoin|2022|   10|  1|  10|\n",
      "|hello everyone si...|1.66462234E9|        solana|2022|   10|  1|  11|\n",
      "+--------------------+------------+--------------+----+-----+---+----+\n",
      "only showing top 20 rows\n",
      "\n"
     ]
    },
    {
     "name": "stderr",
     "output_type": "stream",
     "text": [
      "\r",
      "                                                                                \r"
     ]
    }
   ],
   "source": [
    "test_df.show()"
   ]
  },
  {
   "cell_type": "code",
   "execution_count": 7,
   "id": "e58a5b1a",
   "metadata": {},
   "outputs": [],
   "source": [
    "prediction = loaded_model.transform(test_df)"
   ]
  },
  {
   "cell_type": "code",
   "execution_count": 8,
   "id": "f3deba20",
   "metadata": {},
   "outputs": [],
   "source": [
    "results = (prediction.withColumn(\"xs\", vector_to_array(\"probability\"))).select(['prediction'] + [F.col(\"xs\")[1]] + ['created_utc'])\n",
    "results = results.withColumnRenamed('xs[1]', 'probability')\n",
    "results = results.withColumn('created_utc', F.date_format(results.created_utc.cast('timestamp'), \"yyyy-MM-dd HH:00:00\"))\n",
    "results = results.groupBy('created_utc').agg(F.avg('probability'), F.avg('prediction'))"
   ]
  },
  {
   "cell_type": "code",
   "execution_count": 9,
   "id": "f029e33c",
   "metadata": {},
   "outputs": [
    {
     "name": "stderr",
     "output_type": "stream",
     "text": [
      "[Stage 11:===================================================>      (8 + 1) / 9]\r"
     ]
    },
    {
     "name": "stdout",
     "output_type": "stream",
     "text": [
      "+----------+------------------+------------------+\n",
      "|      date|   avg_probability|    avg_prediction|\n",
      "+----------+------------------+------------------+\n",
      "|2022-09-16|0.9999999999999988|               1.0|\n",
      "|2022-09-15|0.5311723408744236|               0.5|\n",
      "|2022-09-15|0.9145162730257073|               1.0|\n",
      "|2022-09-15|0.3102653971279222|0.3333333333333333|\n",
      "|2022-09-14|0.7993924780262095|               0.8|\n",
      "|2022-09-17|0.9412943891486791|               1.0|\n",
      "|2022-09-15|0.9998260500941284|               1.0|\n",
      "|2022-09-17|0.5082690101268774|               0.5|\n",
      "|2022-09-16|0.6666448334045235|0.6666666666666666|\n",
      "|2022-09-15|0.8561052848048938|              0.75|\n",
      "|2022-09-15|0.9992252032710601|               1.0|\n",
      "|2022-09-16|0.5000129575610124|               0.5|\n",
      "|2022-09-17|0.5800103837403789|0.5714285714285714|\n",
      "|2022-09-15|0.4974571990467472|               0.5|\n",
      "|2022-09-16|0.9999741274133681|               1.0|\n",
      "|2022-09-17|0.9926435053908795|               1.0|\n",
      "|2022-09-16|0.9996505554303563|               1.0|\n",
      "|2022-09-16|               1.0|               1.0|\n",
      "|2022-09-15|0.7051511375363694|0.6666666666666666|\n",
      "|2022-09-15|0.9674071387774585|               1.0|\n",
      "+----------+------------------+------------------+\n",
      "only showing top 20 rows\n",
      "\n"
     ]
    },
    {
     "name": "stderr",
     "output_type": "stream",
     "text": [
      "\r",
      "                                                                                \r"
     ]
    }
   ],
   "source": [
    "results = results.withColumnRenamed('avg(probability)', 'avg_probability')\n",
    "results = results.withColumnRenamed('avg(prediction)', 'avg_prediction')\n",
    "results = results.withColumnRenamed('created_utc', 'date')\n",
    "results = results.withColumn('date', F.date_sub(results['date'], day_shift))\n",
    "results.show()"
   ]
  },
  {
   "cell_type": "code",
   "execution_count": 10,
   "id": "47a7a84f",
   "metadata": {},
   "outputs": [],
   "source": [
    "crypto_df = spark.sql(f'SELECT * FROM crypto_table')"
   ]
  },
  {
   "cell_type": "code",
   "execution_count": 11,
   "id": "863a4dc1",
   "metadata": {},
   "outputs": [],
   "source": [
    "crypto_df = crypto_df.withColumn('date', F.date_format(crypto_df.date.cast('timestamp'), \"yyyy-MM-dd HH:00:00\"))"
   ]
  },
  {
   "cell_type": "code",
   "execution_count": 12,
   "id": "39450e27",
   "metadata": {},
   "outputs": [
    {
     "name": "stderr",
     "output_type": "stream",
     "text": [
      "----------------------------------------\n",
      "Exception happened during processing of request from ('127.0.0.1', 48214)\n",
      "ERROR:root:Exception while sending command.\n",
      "Traceback (most recent call last):\n",
      "  File \"/usr/lib/spark/python/lib/py4j-0.10.9-src.zip/py4j/java_gateway.py\", line 1207, in send_command\n",
      "    raise Py4JNetworkError(\"Answer from Java side is empty\")\n",
      "py4j.protocol.Py4JNetworkError: Answer from Java side is empty\n",
      "\n",
      "During handling of the above exception, another exception occurred:\n",
      "\n",
      "Traceback (most recent call last):\n",
      "  File \"/usr/lib/spark/python/lib/py4j-0.10.9-src.zip/py4j/java_gateway.py\", line 1033, in send_command\n",
      "    response = connection.send_command(command)\n",
      "  File \"/usr/lib/spark/python/lib/py4j-0.10.9-src.zip/py4j/java_gateway.py\", line 1211, in send_command\n",
      "    raise Py4JNetworkError(\n",
      "py4j.protocol.Py4JNetworkError: Error while receiving\n",
      "Traceback (most recent call last):\n",
      "  File \"/opt/conda/miniconda3/lib/python3.8/socketserver.py\", line 316, in _handle_request_noblock\n",
      "    self.process_request(request, client_address)\n",
      "  File \"/opt/conda/miniconda3/lib/python3.8/socketserver.py\", line 347, in process_request\n",
      "    self.finish_request(request, client_address)\n",
      "  File \"/opt/conda/miniconda3/lib/python3.8/socketserver.py\", line 360, in finish_request\n",
      "    self.RequestHandlerClass(request, client_address, self)\n",
      "  File \"/opt/conda/miniconda3/lib/python3.8/socketserver.py\", line 747, in __init__\n",
      "    self.handle()\n",
      "  File \"/usr/lib/spark/python/pyspark/accumulators.py\", line 262, in handle\n",
      "    poll(accum_updates)\n",
      "  File \"/usr/lib/spark/python/pyspark/accumulators.py\", line 235, in poll\n",
      "    if func():\n",
      "  File \"/usr/lib/spark/python/pyspark/accumulators.py\", line 239, in accum_updates\n",
      "    num_updates = read_int(self.rfile)\n",
      "  File \"/usr/lib/spark/python/pyspark/serializers.py\", line 564, in read_int\n",
      "    raise EOFError\n",
      "EOFError\n",
      "----------------------------------------\n",
      "ERROR:py4j.java_gateway:An error occurred while trying to connect to the Java server (127.0.0.1:46273)\n",
      "Traceback (most recent call last):\n",
      "  File \"/opt/conda/miniconda3/lib/python3.8/site-packages/IPython/core/interactiveshell.py\", line 3433, in run_code\n",
      "    exec(code_obj, self.user_global_ns, self.user_ns)\n",
      "  File \"/tmp/ipykernel_11737/4115056868.py\", line 1, in <module>\n",
      "    results.join(crypto_df,results.date ==  crypto_df.date,\"left\").show()\n",
      "  File \"/usr/lib/spark/python/pyspark/sql/dataframe.py\", line 484, in show\n",
      "    print(self._jdf.showString(n, 20, vertical))\n",
      "  File \"/usr/lib/spark/python/lib/py4j-0.10.9-src.zip/py4j/java_gateway.py\", line 1304, in __call__\n",
      "    return_value = get_return_value(\n",
      "  File \"/usr/lib/spark/python/pyspark/sql/utils.py\", line 111, in deco\n",
      "    return f(*a, **kw)\n",
      "  File \"/usr/lib/spark/python/lib/py4j-0.10.9-src.zip/py4j/protocol.py\", line 334, in get_return_value\n",
      "    raise Py4JError(\n",
      "py4j.protocol.Py4JError: An error occurred while calling o268.showString\n",
      "\n",
      "During handling of the above exception, another exception occurred:\n",
      "\n",
      "Traceback (most recent call last):\n",
      "  File \"/usr/lib/spark/python/lib/py4j-0.10.9-src.zip/py4j/java_gateway.py\", line 977, in _get_connection\n",
      "    connection = self.deque.pop()\n",
      "IndexError: pop from an empty deque\n",
      "\n",
      "During handling of the above exception, another exception occurred:\n",
      "\n",
      "Traceback (most recent call last):\n",
      "  File \"/usr/lib/spark/python/lib/py4j-0.10.9-src.zip/py4j/java_gateway.py\", line 1115, in start\n",
      "    self.socket.connect((self.address, self.port))\n",
      "ConnectionRefusedError: [Errno 111] Connection refused\n",
      "ERROR:py4j.java_gateway:An error occurred while trying to connect to the Java server (127.0.0.1:46273)\n",
      "Traceback (most recent call last):\n",
      "  File \"/opt/conda/miniconda3/lib/python3.8/site-packages/IPython/core/interactiveshell.py\", line 3433, in run_code\n",
      "    exec(code_obj, self.user_global_ns, self.user_ns)\n",
      "  File \"/tmp/ipykernel_11737/4115056868.py\", line 1, in <module>\n",
      "    results.join(crypto_df,results.date ==  crypto_df.date,\"left\").show()\n",
      "  File \"/usr/lib/spark/python/pyspark/sql/dataframe.py\", line 484, in show\n",
      "    print(self._jdf.showString(n, 20, vertical))\n",
      "  File \"/usr/lib/spark/python/lib/py4j-0.10.9-src.zip/py4j/java_gateway.py\", line 1304, in __call__\n",
      "    return_value = get_return_value(\n",
      "  File \"/usr/lib/spark/python/pyspark/sql/utils.py\", line 111, in deco\n",
      "    return f(*a, **kw)\n",
      "  File \"/usr/lib/spark/python/lib/py4j-0.10.9-src.zip/py4j/protocol.py\", line 334, in get_return_value\n",
      "    raise Py4JError(\n",
      "py4j.protocol.Py4JError: An error occurred while calling o268.showString\n",
      "\n",
      "During handling of the above exception, another exception occurred:\n",
      "\n",
      "Traceback (most recent call last):\n",
      "  File \"/usr/lib/spark/python/lib/py4j-0.10.9-src.zip/py4j/java_gateway.py\", line 977, in _get_connection\n",
      "    connection = self.deque.pop()\n",
      "IndexError: pop from an empty deque\n",
      "\n",
      "During handling of the above exception, another exception occurred:\n",
      "\n",
      "Traceback (most recent call last):\n",
      "  File \"/usr/lib/spark/python/lib/py4j-0.10.9-src.zip/py4j/java_gateway.py\", line 1115, in start\n",
      "    self.socket.connect((self.address, self.port))\n",
      "ConnectionRefusedError: [Errno 111] Connection refused\n",
      "ERROR:py4j.java_gateway:An error occurred while trying to connect to the Java server (127.0.0.1:46273)\n",
      "Traceback (most recent call last):\n",
      "  File \"/opt/conda/miniconda3/lib/python3.8/site-packages/IPython/core/interactiveshell.py\", line 3433, in run_code\n",
      "    exec(code_obj, self.user_global_ns, self.user_ns)\n",
      "  File \"/tmp/ipykernel_11737/4115056868.py\", line 1, in <module>\n",
      "    results.join(crypto_df,results.date ==  crypto_df.date,\"left\").show()\n",
      "  File \"/usr/lib/spark/python/pyspark/sql/dataframe.py\", line 484, in show\n",
      "    print(self._jdf.showString(n, 20, vertical))\n",
      "  File \"/usr/lib/spark/python/lib/py4j-0.10.9-src.zip/py4j/java_gateway.py\", line 1304, in __call__\n",
      "    return_value = get_return_value(\n",
      "  File \"/usr/lib/spark/python/pyspark/sql/utils.py\", line 111, in deco\n",
      "    return f(*a, **kw)\n",
      "  File \"/usr/lib/spark/python/lib/py4j-0.10.9-src.zip/py4j/protocol.py\", line 334, in get_return_value\n",
      "    raise Py4JError(\n",
      "py4j.protocol.Py4JError: An error occurred while calling o268.showString\n",
      "\n",
      "During handling of the above exception, another exception occurred:\n",
      "\n",
      "Traceback (most recent call last):\n",
      "  File \"/usr/lib/spark/python/lib/py4j-0.10.9-src.zip/py4j/java_gateway.py\", line 977, in _get_connection\n",
      "    connection = self.deque.pop()\n",
      "IndexError: pop from an empty deque\n",
      "\n",
      "During handling of the above exception, another exception occurred:\n",
      "\n",
      "Traceback (most recent call last):\n",
      "  File \"/usr/lib/spark/python/lib/py4j-0.10.9-src.zip/py4j/java_gateway.py\", line 1115, in start\n",
      "    self.socket.connect((self.address, self.port))\n",
      "ConnectionRefusedError: [Errno 111] Connection refused\n",
      "ERROR:py4j.java_gateway:An error occurred while trying to connect to the Java server (127.0.0.1:46273)\n",
      "Traceback (most recent call last):\n",
      "  File \"/opt/conda/miniconda3/lib/python3.8/site-packages/IPython/core/interactiveshell.py\", line 3433, in run_code\n",
      "    exec(code_obj, self.user_global_ns, self.user_ns)\n",
      "  File \"/tmp/ipykernel_11737/4115056868.py\", line 1, in <module>\n",
      "    results.join(crypto_df,results.date ==  crypto_df.date,\"left\").show()\n",
      "  File \"/usr/lib/spark/python/pyspark/sql/dataframe.py\", line 484, in show\n",
      "    print(self._jdf.showString(n, 20, vertical))\n",
      "  File \"/usr/lib/spark/python/lib/py4j-0.10.9-src.zip/py4j/java_gateway.py\", line 1304, in __call__\n",
      "    return_value = get_return_value(\n",
      "  File \"/usr/lib/spark/python/pyspark/sql/utils.py\", line 111, in deco\n",
      "    return f(*a, **kw)\n",
      "  File \"/usr/lib/spark/python/lib/py4j-0.10.9-src.zip/py4j/protocol.py\", line 334, in get_return_value\n",
      "    raise Py4JError(\n",
      "py4j.protocol.Py4JError: An error occurred while calling o268.showString\n",
      "\n",
      "During handling of the above exception, another exception occurred:\n",
      "\n",
      "Traceback (most recent call last):\n",
      "  File \"/usr/lib/spark/python/lib/py4j-0.10.9-src.zip/py4j/java_gateway.py\", line 977, in _get_connection\n",
      "    connection = self.deque.pop()\n",
      "IndexError: pop from an empty deque\n",
      "\n",
      "During handling of the above exception, another exception occurred:\n",
      "\n",
      "Traceback (most recent call last):\n",
      "  File \"/usr/lib/spark/python/lib/py4j-0.10.9-src.zip/py4j/java_gateway.py\", line 1115, in start\n",
      "    self.socket.connect((self.address, self.port))\n",
      "ConnectionRefusedError: [Errno 111] Connection refused\n"
     ]
    },
    {
     "name": "stderr",
     "output_type": "stream",
     "text": [
      "ERROR:py4j.java_gateway:An error occurred while trying to connect to the Java server (127.0.0.1:46273)\n",
      "Traceback (most recent call last):\n",
      "  File \"/opt/conda/miniconda3/lib/python3.8/site-packages/IPython/core/interactiveshell.py\", line 3433, in run_code\n",
      "    exec(code_obj, self.user_global_ns, self.user_ns)\n",
      "  File \"/tmp/ipykernel_11737/4115056868.py\", line 1, in <module>\n",
      "    results.join(crypto_df,results.date ==  crypto_df.date,\"left\").show()\n",
      "  File \"/usr/lib/spark/python/pyspark/sql/dataframe.py\", line 484, in show\n",
      "    print(self._jdf.showString(n, 20, vertical))\n",
      "  File \"/usr/lib/spark/python/lib/py4j-0.10.9-src.zip/py4j/java_gateway.py\", line 1304, in __call__\n",
      "    return_value = get_return_value(\n",
      "  File \"/usr/lib/spark/python/pyspark/sql/utils.py\", line 111, in deco\n",
      "    return f(*a, **kw)\n",
      "  File \"/usr/lib/spark/python/lib/py4j-0.10.9-src.zip/py4j/protocol.py\", line 334, in get_return_value\n",
      "    raise Py4JError(\n",
      "py4j.protocol.Py4JError: An error occurred while calling o268.showString\n",
      "\n",
      "During handling of the above exception, another exception occurred:\n",
      "\n",
      "Traceback (most recent call last):\n",
      "  File \"/usr/lib/spark/python/lib/py4j-0.10.9-src.zip/py4j/java_gateway.py\", line 977, in _get_connection\n",
      "    connection = self.deque.pop()\n",
      "IndexError: pop from an empty deque\n",
      "\n",
      "During handling of the above exception, another exception occurred:\n",
      "\n",
      "Traceback (most recent call last):\n",
      "  File \"/usr/lib/spark/python/lib/py4j-0.10.9-src.zip/py4j/java_gateway.py\", line 1115, in start\n",
      "    self.socket.connect((self.address, self.port))\n",
      "ConnectionRefusedError: [Errno 111] Connection refused\n",
      "ERROR:py4j.java_gateway:An error occurred while trying to connect to the Java server (127.0.0.1:46273)\n",
      "Traceback (most recent call last):\n",
      "  File \"/opt/conda/miniconda3/lib/python3.8/site-packages/IPython/core/interactiveshell.py\", line 3433, in run_code\n",
      "    exec(code_obj, self.user_global_ns, self.user_ns)\n",
      "  File \"/tmp/ipykernel_11737/4115056868.py\", line 1, in <module>\n",
      "    results.join(crypto_df,results.date ==  crypto_df.date,\"left\").show()\n",
      "  File \"/usr/lib/spark/python/pyspark/sql/dataframe.py\", line 484, in show\n",
      "    print(self._jdf.showString(n, 20, vertical))\n",
      "  File \"/usr/lib/spark/python/lib/py4j-0.10.9-src.zip/py4j/java_gateway.py\", line 1304, in __call__\n",
      "    return_value = get_return_value(\n",
      "  File \"/usr/lib/spark/python/pyspark/sql/utils.py\", line 111, in deco\n",
      "    return f(*a, **kw)\n",
      "  File \"/usr/lib/spark/python/lib/py4j-0.10.9-src.zip/py4j/protocol.py\", line 334, in get_return_value\n",
      "    raise Py4JError(\n",
      "py4j.protocol.Py4JError: An error occurred while calling o268.showString\n",
      "\n",
      "During handling of the above exception, another exception occurred:\n",
      "\n",
      "Traceback (most recent call last):\n",
      "  File \"/usr/lib/spark/python/lib/py4j-0.10.9-src.zip/py4j/java_gateway.py\", line 977, in _get_connection\n",
      "    connection = self.deque.pop()\n",
      "IndexError: pop from an empty deque\n",
      "\n",
      "During handling of the above exception, another exception occurred:\n",
      "\n",
      "Traceback (most recent call last):\n",
      "  File \"/usr/lib/spark/python/lib/py4j-0.10.9-src.zip/py4j/java_gateway.py\", line 1115, in start\n",
      "    self.socket.connect((self.address, self.port))\n",
      "ConnectionRefusedError: [Errno 111] Connection refused\n",
      "ERROR:py4j.java_gateway:An error occurred while trying to connect to the Java server (127.0.0.1:46273)\n",
      "Traceback (most recent call last):\n",
      "  File \"/opt/conda/miniconda3/lib/python3.8/site-packages/IPython/core/interactiveshell.py\", line 3433, in run_code\n",
      "    exec(code_obj, self.user_global_ns, self.user_ns)\n",
      "  File \"/tmp/ipykernel_11737/4115056868.py\", line 1, in <module>\n",
      "    results.join(crypto_df,results.date ==  crypto_df.date,\"left\").show()\n",
      "  File \"/usr/lib/spark/python/pyspark/sql/dataframe.py\", line 484, in show\n",
      "    print(self._jdf.showString(n, 20, vertical))\n",
      "  File \"/usr/lib/spark/python/lib/py4j-0.10.9-src.zip/py4j/java_gateway.py\", line 1304, in __call__\n",
      "    return_value = get_return_value(\n",
      "  File \"/usr/lib/spark/python/pyspark/sql/utils.py\", line 111, in deco\n",
      "    return f(*a, **kw)\n",
      "  File \"/usr/lib/spark/python/lib/py4j-0.10.9-src.zip/py4j/protocol.py\", line 334, in get_return_value\n",
      "    raise Py4JError(\n",
      "py4j.protocol.Py4JError: An error occurred while calling o268.showString\n",
      "\n",
      "During handling of the above exception, another exception occurred:\n",
      "\n",
      "Traceback (most recent call last):\n",
      "  File \"/usr/lib/spark/python/lib/py4j-0.10.9-src.zip/py4j/java_gateway.py\", line 977, in _get_connection\n",
      "    connection = self.deque.pop()\n",
      "IndexError: pop from an empty deque\n",
      "\n",
      "During handling of the above exception, another exception occurred:\n",
      "\n",
      "Traceback (most recent call last):\n",
      "  File \"/usr/lib/spark/python/lib/py4j-0.10.9-src.zip/py4j/java_gateway.py\", line 1115, in start\n",
      "    self.socket.connect((self.address, self.port))\n",
      "ConnectionRefusedError: [Errno 111] Connection refused\n",
      "ERROR:py4j.java_gateway:An error occurred while trying to connect to the Java server (127.0.0.1:46273)\n",
      "Traceback (most recent call last):\n",
      "  File \"/opt/conda/miniconda3/lib/python3.8/site-packages/IPython/core/interactiveshell.py\", line 3433, in run_code\n",
      "    exec(code_obj, self.user_global_ns, self.user_ns)\n",
      "  File \"/tmp/ipykernel_11737/4115056868.py\", line 1, in <module>\n",
      "    results.join(crypto_df,results.date ==  crypto_df.date,\"left\").show()\n",
      "  File \"/usr/lib/spark/python/pyspark/sql/dataframe.py\", line 484, in show\n",
      "    print(self._jdf.showString(n, 20, vertical))\n",
      "  File \"/usr/lib/spark/python/lib/py4j-0.10.9-src.zip/py4j/java_gateway.py\", line 1304, in __call__\n",
      "    return_value = get_return_value(\n",
      "  File \"/usr/lib/spark/python/pyspark/sql/utils.py\", line 111, in deco\n",
      "    return f(*a, **kw)\n",
      "  File \"/usr/lib/spark/python/lib/py4j-0.10.9-src.zip/py4j/protocol.py\", line 334, in get_return_value\n",
      "    raise Py4JError(\n",
      "py4j.protocol.Py4JError: An error occurred while calling o268.showString\n",
      "\n",
      "During handling of the above exception, another exception occurred:\n",
      "\n",
      "Traceback (most recent call last):\n",
      "  File \"/usr/lib/spark/python/lib/py4j-0.10.9-src.zip/py4j/java_gateway.py\", line 977, in _get_connection\n",
      "    connection = self.deque.pop()\n",
      "IndexError: pop from an empty deque\n",
      "\n",
      "During handling of the above exception, another exception occurred:\n",
      "\n",
      "Traceback (most recent call last):\n",
      "  File \"/usr/lib/spark/python/lib/py4j-0.10.9-src.zip/py4j/java_gateway.py\", line 1115, in start\n",
      "    self.socket.connect((self.address, self.port))\n",
      "ConnectionRefusedError: [Errno 111] Connection refused\n",
      "ERROR:py4j.java_gateway:An error occurred while trying to connect to the Java server (127.0.0.1:46273)\n",
      "Traceback (most recent call last):\n",
      "  File \"/opt/conda/miniconda3/lib/python3.8/site-packages/IPython/core/interactiveshell.py\", line 3433, in run_code\n",
      "    exec(code_obj, self.user_global_ns, self.user_ns)\n",
      "  File \"/tmp/ipykernel_11737/4115056868.py\", line 1, in <module>\n",
      "    results.join(crypto_df,results.date ==  crypto_df.date,\"left\").show()\n",
      "  File \"/usr/lib/spark/python/pyspark/sql/dataframe.py\", line 484, in show\n",
      "    print(self._jdf.showString(n, 20, vertical))\n",
      "  File \"/usr/lib/spark/python/lib/py4j-0.10.9-src.zip/py4j/java_gateway.py\", line 1304, in __call__\n",
      "    return_value = get_return_value(\n",
      "  File \"/usr/lib/spark/python/pyspark/sql/utils.py\", line 111, in deco\n",
      "    return f(*a, **kw)\n",
      "  File \"/usr/lib/spark/python/lib/py4j-0.10.9-src.zip/py4j/protocol.py\", line 334, in get_return_value\n",
      "    raise Py4JError(\n",
      "py4j.protocol.Py4JError: An error occurred while calling o268.showString\n",
      "\n",
      "During handling of the above exception, another exception occurred:\n",
      "\n",
      "Traceback (most recent call last):\n",
      "  File \"/usr/lib/spark/python/lib/py4j-0.10.9-src.zip/py4j/java_gateway.py\", line 977, in _get_connection\n",
      "    connection = self.deque.pop()\n",
      "IndexError: pop from an empty deque\n",
      "\n",
      "During handling of the above exception, another exception occurred:\n",
      "\n",
      "Traceback (most recent call last):\n",
      "  File \"/usr/lib/spark/python/lib/py4j-0.10.9-src.zip/py4j/java_gateway.py\", line 1115, in start\n",
      "    self.socket.connect((self.address, self.port))\n",
      "ConnectionRefusedError: [Errno 111] Connection refused\n",
      "ERROR:py4j.java_gateway:An error occurred while trying to connect to the Java server (127.0.0.1:46273)\n",
      "Traceback (most recent call last):\n",
      "  File \"/opt/conda/miniconda3/lib/python3.8/site-packages/IPython/core/interactiveshell.py\", line 3433, in run_code\n",
      "    exec(code_obj, self.user_global_ns, self.user_ns)\n",
      "  File \"/tmp/ipykernel_11737/4115056868.py\", line 1, in <module>\n",
      "    results.join(crypto_df,results.date ==  crypto_df.date,\"left\").show()\n",
      "  File \"/usr/lib/spark/python/pyspark/sql/dataframe.py\", line 484, in show\n",
      "    print(self._jdf.showString(n, 20, vertical))\n",
      "  File \"/usr/lib/spark/python/lib/py4j-0.10.9-src.zip/py4j/java_gateway.py\", line 1304, in __call__\n",
      "    return_value = get_return_value(\n",
      "  File \"/usr/lib/spark/python/pyspark/sql/utils.py\", line 111, in deco\n",
      "    return f(*a, **kw)\n",
      "  File \"/usr/lib/spark/python/lib/py4j-0.10.9-src.zip/py4j/protocol.py\", line 334, in get_return_value\n",
      "    raise Py4JError(\n",
      "py4j.protocol.Py4JError: An error occurred while calling o268.showString\n",
      "\n",
      "During handling of the above exception, another exception occurred:\n",
      "\n",
      "Traceback (most recent call last):\n",
      "  File \"/usr/lib/spark/python/lib/py4j-0.10.9-src.zip/py4j/java_gateway.py\", line 977, in _get_connection\n",
      "    connection = self.deque.pop()\n",
      "IndexError: pop from an empty deque\n",
      "\n",
      "During handling of the above exception, another exception occurred:\n",
      "\n",
      "Traceback (most recent call last):\n",
      "  File \"/usr/lib/spark/python/lib/py4j-0.10.9-src.zip/py4j/java_gateway.py\", line 1115, in start\n",
      "    self.socket.connect((self.address, self.port))\n",
      "ConnectionRefusedError: [Errno 111] Connection refused\n"
     ]
    },
    {
     "name": "stderr",
     "output_type": "stream",
     "text": [
      "ERROR:py4j.java_gateway:An error occurred while trying to connect to the Java server (127.0.0.1:46273)\n",
      "Traceback (most recent call last):\n",
      "  File \"/opt/conda/miniconda3/lib/python3.8/site-packages/IPython/core/interactiveshell.py\", line 3433, in run_code\n",
      "    exec(code_obj, self.user_global_ns, self.user_ns)\n",
      "  File \"/tmp/ipykernel_11737/4115056868.py\", line 1, in <module>\n",
      "    results.join(crypto_df,results.date ==  crypto_df.date,\"left\").show()\n",
      "  File \"/usr/lib/spark/python/pyspark/sql/dataframe.py\", line 484, in show\n",
      "    print(self._jdf.showString(n, 20, vertical))\n",
      "  File \"/usr/lib/spark/python/lib/py4j-0.10.9-src.zip/py4j/java_gateway.py\", line 1304, in __call__\n",
      "    return_value = get_return_value(\n",
      "  File \"/usr/lib/spark/python/pyspark/sql/utils.py\", line 111, in deco\n",
      "    return f(*a, **kw)\n",
      "  File \"/usr/lib/spark/python/lib/py4j-0.10.9-src.zip/py4j/protocol.py\", line 334, in get_return_value\n",
      "    raise Py4JError(\n",
      "py4j.protocol.Py4JError: An error occurred while calling o268.showString\n",
      "\n",
      "During handling of the above exception, another exception occurred:\n",
      "\n",
      "Traceback (most recent call last):\n",
      "  File \"/usr/lib/spark/python/lib/py4j-0.10.9-src.zip/py4j/java_gateway.py\", line 977, in _get_connection\n",
      "    connection = self.deque.pop()\n",
      "IndexError: pop from an empty deque\n",
      "\n",
      "During handling of the above exception, another exception occurred:\n",
      "\n",
      "Traceback (most recent call last):\n",
      "  File \"/usr/lib/spark/python/lib/py4j-0.10.9-src.zip/py4j/java_gateway.py\", line 1115, in start\n",
      "    self.socket.connect((self.address, self.port))\n",
      "ConnectionRefusedError: [Errno 111] Connection refused\n",
      "ERROR:py4j.java_gateway:An error occurred while trying to connect to the Java server (127.0.0.1:46273)\n",
      "Traceback (most recent call last):\n",
      "  File \"/opt/conda/miniconda3/lib/python3.8/site-packages/IPython/core/interactiveshell.py\", line 3433, in run_code\n",
      "    exec(code_obj, self.user_global_ns, self.user_ns)\n",
      "  File \"/tmp/ipykernel_11737/4115056868.py\", line 1, in <module>\n",
      "    results.join(crypto_df,results.date ==  crypto_df.date,\"left\").show()\n",
      "  File \"/usr/lib/spark/python/pyspark/sql/dataframe.py\", line 484, in show\n",
      "    print(self._jdf.showString(n, 20, vertical))\n",
      "  File \"/usr/lib/spark/python/lib/py4j-0.10.9-src.zip/py4j/java_gateway.py\", line 1304, in __call__\n",
      "    return_value = get_return_value(\n",
      "  File \"/usr/lib/spark/python/pyspark/sql/utils.py\", line 111, in deco\n",
      "    return f(*a, **kw)\n",
      "  File \"/usr/lib/spark/python/lib/py4j-0.10.9-src.zip/py4j/protocol.py\", line 334, in get_return_value\n",
      "    raise Py4JError(\n",
      "py4j.protocol.Py4JError: An error occurred while calling o268.showString\n",
      "\n",
      "During handling of the above exception, another exception occurred:\n",
      "\n",
      "Traceback (most recent call last):\n",
      "  File \"/usr/lib/spark/python/lib/py4j-0.10.9-src.zip/py4j/java_gateway.py\", line 977, in _get_connection\n",
      "    connection = self.deque.pop()\n",
      "IndexError: pop from an empty deque\n",
      "\n",
      "During handling of the above exception, another exception occurred:\n",
      "\n",
      "Traceback (most recent call last):\n",
      "  File \"/usr/lib/spark/python/lib/py4j-0.10.9-src.zip/py4j/java_gateway.py\", line 1115, in start\n",
      "    self.socket.connect((self.address, self.port))\n",
      "ConnectionRefusedError: [Errno 111] Connection refused\n",
      "ERROR:py4j.java_gateway:An error occurred while trying to connect to the Java server (127.0.0.1:46273)\n",
      "Traceback (most recent call last):\n",
      "  File \"/opt/conda/miniconda3/lib/python3.8/site-packages/IPython/core/interactiveshell.py\", line 3433, in run_code\n",
      "    exec(code_obj, self.user_global_ns, self.user_ns)\n",
      "  File \"/tmp/ipykernel_11737/4115056868.py\", line 1, in <module>\n",
      "    results.join(crypto_df,results.date ==  crypto_df.date,\"left\").show()\n",
      "  File \"/usr/lib/spark/python/pyspark/sql/dataframe.py\", line 484, in show\n",
      "    print(self._jdf.showString(n, 20, vertical))\n",
      "  File \"/usr/lib/spark/python/lib/py4j-0.10.9-src.zip/py4j/java_gateway.py\", line 1304, in __call__\n",
      "    return_value = get_return_value(\n",
      "  File \"/usr/lib/spark/python/pyspark/sql/utils.py\", line 111, in deco\n",
      "    return f(*a, **kw)\n",
      "  File \"/usr/lib/spark/python/lib/py4j-0.10.9-src.zip/py4j/protocol.py\", line 334, in get_return_value\n",
      "    raise Py4JError(\n",
      "py4j.protocol.Py4JError: An error occurred while calling o268.showString\n",
      "\n",
      "During handling of the above exception, another exception occurred:\n",
      "\n",
      "Traceback (most recent call last):\n",
      "  File \"/usr/lib/spark/python/lib/py4j-0.10.9-src.zip/py4j/java_gateway.py\", line 977, in _get_connection\n",
      "    connection = self.deque.pop()\n",
      "IndexError: pop from an empty deque\n",
      "\n",
      "During handling of the above exception, another exception occurred:\n",
      "\n",
      "Traceback (most recent call last):\n",
      "  File \"/usr/lib/spark/python/lib/py4j-0.10.9-src.zip/py4j/java_gateway.py\", line 1115, in start\n",
      "    self.socket.connect((self.address, self.port))\n",
      "ConnectionRefusedError: [Errno 111] Connection refused\n",
      "ERROR:py4j.java_gateway:An error occurred while trying to connect to the Java server (127.0.0.1:46273)\n",
      "Traceback (most recent call last):\n",
      "  File \"/opt/conda/miniconda3/lib/python3.8/site-packages/IPython/core/interactiveshell.py\", line 3433, in run_code\n",
      "    exec(code_obj, self.user_global_ns, self.user_ns)\n",
      "  File \"/tmp/ipykernel_11737/4115056868.py\", line 1, in <module>\n",
      "    results.join(crypto_df,results.date ==  crypto_df.date,\"left\").show()\n",
      "  File \"/usr/lib/spark/python/pyspark/sql/dataframe.py\", line 484, in show\n",
      "    print(self._jdf.showString(n, 20, vertical))\n",
      "  File \"/usr/lib/spark/python/lib/py4j-0.10.9-src.zip/py4j/java_gateway.py\", line 1304, in __call__\n",
      "    return_value = get_return_value(\n",
      "  File \"/usr/lib/spark/python/pyspark/sql/utils.py\", line 111, in deco\n",
      "    return f(*a, **kw)\n",
      "  File \"/usr/lib/spark/python/lib/py4j-0.10.9-src.zip/py4j/protocol.py\", line 334, in get_return_value\n",
      "    raise Py4JError(\n",
      "py4j.protocol.Py4JError: An error occurred while calling o268.showString\n",
      "\n",
      "During handling of the above exception, another exception occurred:\n",
      "\n",
      "Traceback (most recent call last):\n",
      "  File \"/usr/lib/spark/python/lib/py4j-0.10.9-src.zip/py4j/java_gateway.py\", line 977, in _get_connection\n",
      "    connection = self.deque.pop()\n",
      "IndexError: pop from an empty deque\n",
      "\n",
      "During handling of the above exception, another exception occurred:\n",
      "\n",
      "Traceback (most recent call last):\n",
      "  File \"/usr/lib/spark/python/lib/py4j-0.10.9-src.zip/py4j/java_gateway.py\", line 1115, in start\n",
      "    self.socket.connect((self.address, self.port))\n",
      "ConnectionRefusedError: [Errno 111] Connection refused\n",
      "ERROR:py4j.java_gateway:An error occurred while trying to connect to the Java server (127.0.0.1:46273)\n",
      "Traceback (most recent call last):\n",
      "  File \"/opt/conda/miniconda3/lib/python3.8/site-packages/IPython/core/interactiveshell.py\", line 3433, in run_code\n",
      "    exec(code_obj, self.user_global_ns, self.user_ns)\n",
      "  File \"/tmp/ipykernel_11737/4115056868.py\", line 1, in <module>\n",
      "    results.join(crypto_df,results.date ==  crypto_df.date,\"left\").show()\n",
      "  File \"/usr/lib/spark/python/pyspark/sql/dataframe.py\", line 484, in show\n",
      "    print(self._jdf.showString(n, 20, vertical))\n",
      "  File \"/usr/lib/spark/python/lib/py4j-0.10.9-src.zip/py4j/java_gateway.py\", line 1304, in __call__\n",
      "    return_value = get_return_value(\n",
      "  File \"/usr/lib/spark/python/pyspark/sql/utils.py\", line 111, in deco\n",
      "    return f(*a, **kw)\n",
      "  File \"/usr/lib/spark/python/lib/py4j-0.10.9-src.zip/py4j/protocol.py\", line 334, in get_return_value\n",
      "    raise Py4JError(\n",
      "py4j.protocol.Py4JError: An error occurred while calling o268.showString\n",
      "\n",
      "During handling of the above exception, another exception occurred:\n",
      "\n",
      "Traceback (most recent call last):\n",
      "  File \"/usr/lib/spark/python/lib/py4j-0.10.9-src.zip/py4j/java_gateway.py\", line 977, in _get_connection\n",
      "    connection = self.deque.pop()\n",
      "IndexError: pop from an empty deque\n",
      "\n",
      "During handling of the above exception, another exception occurred:\n",
      "\n",
      "Traceback (most recent call last):\n",
      "  File \"/usr/lib/spark/python/lib/py4j-0.10.9-src.zip/py4j/java_gateway.py\", line 1115, in start\n",
      "    self.socket.connect((self.address, self.port))\n",
      "ConnectionRefusedError: [Errno 111] Connection refused\n",
      "ERROR:py4j.java_gateway:An error occurred while trying to connect to the Java server (127.0.0.1:46273)\n",
      "Traceback (most recent call last):\n",
      "  File \"/opt/conda/miniconda3/lib/python3.8/site-packages/IPython/core/interactiveshell.py\", line 3433, in run_code\n",
      "    exec(code_obj, self.user_global_ns, self.user_ns)\n",
      "  File \"/tmp/ipykernel_11737/4115056868.py\", line 1, in <module>\n",
      "    results.join(crypto_df,results.date ==  crypto_df.date,\"left\").show()\n",
      "  File \"/usr/lib/spark/python/pyspark/sql/dataframe.py\", line 484, in show\n",
      "    print(self._jdf.showString(n, 20, vertical))\n",
      "  File \"/usr/lib/spark/python/lib/py4j-0.10.9-src.zip/py4j/java_gateway.py\", line 1304, in __call__\n",
      "    return_value = get_return_value(\n",
      "  File \"/usr/lib/spark/python/pyspark/sql/utils.py\", line 111, in deco\n",
      "    return f(*a, **kw)\n",
      "  File \"/usr/lib/spark/python/lib/py4j-0.10.9-src.zip/py4j/protocol.py\", line 334, in get_return_value\n",
      "    raise Py4JError(\n",
      "py4j.protocol.Py4JError: An error occurred while calling o268.showString\n",
      "\n",
      "During handling of the above exception, another exception occurred:\n",
      "\n",
      "Traceback (most recent call last):\n",
      "  File \"/usr/lib/spark/python/lib/py4j-0.10.9-src.zip/py4j/java_gateway.py\", line 977, in _get_connection\n",
      "    connection = self.deque.pop()\n",
      "IndexError: pop from an empty deque\n",
      "\n",
      "During handling of the above exception, another exception occurred:\n",
      "\n",
      "Traceback (most recent call last):\n",
      "  File \"/usr/lib/spark/python/lib/py4j-0.10.9-src.zip/py4j/java_gateway.py\", line 1115, in start\n",
      "    self.socket.connect((self.address, self.port))\n",
      "ConnectionRefusedError: [Errno 111] Connection refused\n"
     ]
    },
    {
     "name": "stderr",
     "output_type": "stream",
     "text": [
      "ERROR:py4j.java_gateway:An error occurred while trying to connect to the Java server (127.0.0.1:46273)\n",
      "Traceback (most recent call last):\n",
      "  File \"/opt/conda/miniconda3/lib/python3.8/site-packages/IPython/core/interactiveshell.py\", line 3433, in run_code\n",
      "    exec(code_obj, self.user_global_ns, self.user_ns)\n",
      "  File \"/tmp/ipykernel_11737/4115056868.py\", line 1, in <module>\n",
      "    results.join(crypto_df,results.date ==  crypto_df.date,\"left\").show()\n",
      "  File \"/usr/lib/spark/python/pyspark/sql/dataframe.py\", line 484, in show\n",
      "    print(self._jdf.showString(n, 20, vertical))\n",
      "  File \"/usr/lib/spark/python/lib/py4j-0.10.9-src.zip/py4j/java_gateway.py\", line 1304, in __call__\n",
      "    return_value = get_return_value(\n",
      "  File \"/usr/lib/spark/python/pyspark/sql/utils.py\", line 111, in deco\n",
      "    return f(*a, **kw)\n",
      "  File \"/usr/lib/spark/python/lib/py4j-0.10.9-src.zip/py4j/protocol.py\", line 334, in get_return_value\n",
      "    raise Py4JError(\n",
      "py4j.protocol.Py4JError: An error occurred while calling o268.showString\n",
      "\n",
      "During handling of the above exception, another exception occurred:\n",
      "\n",
      "Traceback (most recent call last):\n",
      "  File \"/usr/lib/spark/python/lib/py4j-0.10.9-src.zip/py4j/java_gateway.py\", line 977, in _get_connection\n",
      "    connection = self.deque.pop()\n",
      "IndexError: pop from an empty deque\n",
      "\n",
      "During handling of the above exception, another exception occurred:\n",
      "\n",
      "Traceback (most recent call last):\n",
      "  File \"/usr/lib/spark/python/lib/py4j-0.10.9-src.zip/py4j/java_gateway.py\", line 1115, in start\n",
      "    self.socket.connect((self.address, self.port))\n",
      "ConnectionRefusedError: [Errno 111] Connection refused\n",
      "ERROR:py4j.java_gateway:An error occurred while trying to connect to the Java server (127.0.0.1:46273)\n",
      "Traceback (most recent call last):\n",
      "  File \"/opt/conda/miniconda3/lib/python3.8/site-packages/IPython/core/interactiveshell.py\", line 3433, in run_code\n",
      "    exec(code_obj, self.user_global_ns, self.user_ns)\n",
      "  File \"/tmp/ipykernel_11737/4115056868.py\", line 1, in <module>\n",
      "    results.join(crypto_df,results.date ==  crypto_df.date,\"left\").show()\n",
      "  File \"/usr/lib/spark/python/pyspark/sql/dataframe.py\", line 484, in show\n",
      "    print(self._jdf.showString(n, 20, vertical))\n",
      "  File \"/usr/lib/spark/python/lib/py4j-0.10.9-src.zip/py4j/java_gateway.py\", line 1304, in __call__\n",
      "    return_value = get_return_value(\n",
      "  File \"/usr/lib/spark/python/pyspark/sql/utils.py\", line 111, in deco\n",
      "    return f(*a, **kw)\n",
      "  File \"/usr/lib/spark/python/lib/py4j-0.10.9-src.zip/py4j/protocol.py\", line 334, in get_return_value\n",
      "    raise Py4JError(\n",
      "py4j.protocol.Py4JError: An error occurred while calling o268.showString\n",
      "\n",
      "During handling of the above exception, another exception occurred:\n",
      "\n",
      "Traceback (most recent call last):\n",
      "  File \"/usr/lib/spark/python/lib/py4j-0.10.9-src.zip/py4j/java_gateway.py\", line 977, in _get_connection\n",
      "    connection = self.deque.pop()\n",
      "IndexError: pop from an empty deque\n",
      "\n",
      "During handling of the above exception, another exception occurred:\n",
      "\n",
      "Traceback (most recent call last):\n",
      "  File \"/usr/lib/spark/python/lib/py4j-0.10.9-src.zip/py4j/java_gateway.py\", line 1115, in start\n",
      "    self.socket.connect((self.address, self.port))\n",
      "ConnectionRefusedError: [Errno 111] Connection refused\n",
      "ERROR:py4j.java_gateway:An error occurred while trying to connect to the Java server (127.0.0.1:46273)\n",
      "Traceback (most recent call last):\n",
      "  File \"/opt/conda/miniconda3/lib/python3.8/site-packages/IPython/core/interactiveshell.py\", line 3433, in run_code\n",
      "    exec(code_obj, self.user_global_ns, self.user_ns)\n",
      "  File \"/tmp/ipykernel_11737/4115056868.py\", line 1, in <module>\n",
      "    results.join(crypto_df,results.date ==  crypto_df.date,\"left\").show()\n",
      "  File \"/usr/lib/spark/python/pyspark/sql/dataframe.py\", line 484, in show\n",
      "    print(self._jdf.showString(n, 20, vertical))\n",
      "  File \"/usr/lib/spark/python/lib/py4j-0.10.9-src.zip/py4j/java_gateway.py\", line 1304, in __call__\n",
      "    return_value = get_return_value(\n",
      "  File \"/usr/lib/spark/python/pyspark/sql/utils.py\", line 111, in deco\n",
      "    return f(*a, **kw)\n",
      "  File \"/usr/lib/spark/python/lib/py4j-0.10.9-src.zip/py4j/protocol.py\", line 334, in get_return_value\n",
      "    raise Py4JError(\n",
      "py4j.protocol.Py4JError: An error occurred while calling o268.showString\n",
      "\n",
      "During handling of the above exception, another exception occurred:\n",
      "\n",
      "Traceback (most recent call last):\n",
      "  File \"/usr/lib/spark/python/lib/py4j-0.10.9-src.zip/py4j/java_gateway.py\", line 977, in _get_connection\n",
      "    connection = self.deque.pop()\n",
      "IndexError: pop from an empty deque\n",
      "\n",
      "During handling of the above exception, another exception occurred:\n",
      "\n",
      "Traceback (most recent call last):\n",
      "  File \"/usr/lib/spark/python/lib/py4j-0.10.9-src.zip/py4j/java_gateway.py\", line 1115, in start\n",
      "    self.socket.connect((self.address, self.port))\n",
      "ConnectionRefusedError: [Errno 111] Connection refused\n",
      "ERROR:py4j.java_gateway:An error occurred while trying to connect to the Java server (127.0.0.1:46273)\n",
      "Traceback (most recent call last):\n",
      "  File \"/opt/conda/miniconda3/lib/python3.8/site-packages/IPython/core/interactiveshell.py\", line 3433, in run_code\n",
      "    exec(code_obj, self.user_global_ns, self.user_ns)\n",
      "  File \"/tmp/ipykernel_11737/4115056868.py\", line 1, in <module>\n",
      "    results.join(crypto_df,results.date ==  crypto_df.date,\"left\").show()\n",
      "  File \"/usr/lib/spark/python/pyspark/sql/dataframe.py\", line 484, in show\n",
      "    print(self._jdf.showString(n, 20, vertical))\n",
      "  File \"/usr/lib/spark/python/lib/py4j-0.10.9-src.zip/py4j/java_gateway.py\", line 1304, in __call__\n",
      "    return_value = get_return_value(\n",
      "  File \"/usr/lib/spark/python/pyspark/sql/utils.py\", line 111, in deco\n",
      "    return f(*a, **kw)\n",
      "  File \"/usr/lib/spark/python/lib/py4j-0.10.9-src.zip/py4j/protocol.py\", line 334, in get_return_value\n",
      "    raise Py4JError(\n",
      "py4j.protocol.Py4JError: An error occurred while calling o268.showString\n",
      "\n",
      "During handling of the above exception, another exception occurred:\n",
      "\n",
      "Traceback (most recent call last):\n",
      "  File \"/usr/lib/spark/python/lib/py4j-0.10.9-src.zip/py4j/java_gateway.py\", line 977, in _get_connection\n",
      "    connection = self.deque.pop()\n",
      "IndexError: pop from an empty deque\n",
      "\n",
      "During handling of the above exception, another exception occurred:\n",
      "\n",
      "Traceback (most recent call last):\n",
      "  File \"/usr/lib/spark/python/lib/py4j-0.10.9-src.zip/py4j/java_gateway.py\", line 1115, in start\n",
      "    self.socket.connect((self.address, self.port))\n",
      "ConnectionRefusedError: [Errno 111] Connection refused\n",
      "ERROR:py4j.java_gateway:An error occurred while trying to connect to the Java server (127.0.0.1:46273)\n",
      "Traceback (most recent call last):\n",
      "  File \"/opt/conda/miniconda3/lib/python3.8/site-packages/IPython/core/interactiveshell.py\", line 3433, in run_code\n",
      "    exec(code_obj, self.user_global_ns, self.user_ns)\n",
      "  File \"/tmp/ipykernel_11737/4115056868.py\", line 1, in <module>\n",
      "    results.join(crypto_df,results.date ==  crypto_df.date,\"left\").show()\n",
      "  File \"/usr/lib/spark/python/pyspark/sql/dataframe.py\", line 484, in show\n",
      "    print(self._jdf.showString(n, 20, vertical))\n",
      "  File \"/usr/lib/spark/python/lib/py4j-0.10.9-src.zip/py4j/java_gateway.py\", line 1304, in __call__\n",
      "    return_value = get_return_value(\n",
      "  File \"/usr/lib/spark/python/pyspark/sql/utils.py\", line 111, in deco\n",
      "    return f(*a, **kw)\n",
      "  File \"/usr/lib/spark/python/lib/py4j-0.10.9-src.zip/py4j/protocol.py\", line 334, in get_return_value\n",
      "    raise Py4JError(\n",
      "py4j.protocol.Py4JError: An error occurred while calling o268.showString\n",
      "\n",
      "During handling of the above exception, another exception occurred:\n",
      "\n",
      "Traceback (most recent call last):\n",
      "  File \"/usr/lib/spark/python/lib/py4j-0.10.9-src.zip/py4j/java_gateway.py\", line 977, in _get_connection\n",
      "    connection = self.deque.pop()\n",
      "IndexError: pop from an empty deque\n",
      "\n",
      "During handling of the above exception, another exception occurred:\n",
      "\n",
      "Traceback (most recent call last):\n",
      "  File \"/usr/lib/spark/python/lib/py4j-0.10.9-src.zip/py4j/java_gateway.py\", line 1115, in start\n",
      "    self.socket.connect((self.address, self.port))\n",
      "ConnectionRefusedError: [Errno 111] Connection refused\n",
      "ERROR:py4j.java_gateway:An error occurred while trying to connect to the Java server (127.0.0.1:46273)\n",
      "Traceback (most recent call last):\n",
      "  File \"/opt/conda/miniconda3/lib/python3.8/site-packages/IPython/core/interactiveshell.py\", line 3433, in run_code\n",
      "    exec(code_obj, self.user_global_ns, self.user_ns)\n",
      "  File \"/tmp/ipykernel_11737/4115056868.py\", line 1, in <module>\n",
      "    results.join(crypto_df,results.date ==  crypto_df.date,\"left\").show()\n",
      "  File \"/usr/lib/spark/python/pyspark/sql/dataframe.py\", line 484, in show\n",
      "    print(self._jdf.showString(n, 20, vertical))\n",
      "  File \"/usr/lib/spark/python/lib/py4j-0.10.9-src.zip/py4j/java_gateway.py\", line 1304, in __call__\n",
      "    return_value = get_return_value(\n",
      "  File \"/usr/lib/spark/python/pyspark/sql/utils.py\", line 111, in deco\n",
      "    return f(*a, **kw)\n",
      "  File \"/usr/lib/spark/python/lib/py4j-0.10.9-src.zip/py4j/protocol.py\", line 334, in get_return_value\n",
      "    raise Py4JError(\n",
      "py4j.protocol.Py4JError: An error occurred while calling o268.showString\n",
      "\n",
      "During handling of the above exception, another exception occurred:\n",
      "\n",
      "Traceback (most recent call last):\n",
      "  File \"/usr/lib/spark/python/lib/py4j-0.10.9-src.zip/py4j/java_gateway.py\", line 977, in _get_connection\n",
      "    connection = self.deque.pop()\n",
      "IndexError: pop from an empty deque\n",
      "\n",
      "During handling of the above exception, another exception occurred:\n",
      "\n",
      "Traceback (most recent call last):\n",
      "  File \"/usr/lib/spark/python/lib/py4j-0.10.9-src.zip/py4j/java_gateway.py\", line 1115, in start\n",
      "    self.socket.connect((self.address, self.port))\n",
      "ConnectionRefusedError: [Errno 111] Connection refused\n"
     ]
    },
    {
     "name": "stderr",
     "output_type": "stream",
     "text": [
      "ERROR:py4j.java_gateway:An error occurred while trying to connect to the Java server (127.0.0.1:46273)\n",
      "Traceback (most recent call last):\n",
      "  File \"/opt/conda/miniconda3/lib/python3.8/site-packages/IPython/core/interactiveshell.py\", line 3433, in run_code\n",
      "    exec(code_obj, self.user_global_ns, self.user_ns)\n",
      "  File \"/tmp/ipykernel_11737/4115056868.py\", line 1, in <module>\n",
      "    results.join(crypto_df,results.date ==  crypto_df.date,\"left\").show()\n",
      "  File \"/usr/lib/spark/python/pyspark/sql/dataframe.py\", line 484, in show\n",
      "    print(self._jdf.showString(n, 20, vertical))\n",
      "  File \"/usr/lib/spark/python/lib/py4j-0.10.9-src.zip/py4j/java_gateway.py\", line 1304, in __call__\n",
      "    return_value = get_return_value(\n",
      "  File \"/usr/lib/spark/python/pyspark/sql/utils.py\", line 111, in deco\n",
      "    return f(*a, **kw)\n",
      "  File \"/usr/lib/spark/python/lib/py4j-0.10.9-src.zip/py4j/protocol.py\", line 334, in get_return_value\n",
      "    raise Py4JError(\n",
      "py4j.protocol.Py4JError: An error occurred while calling o268.showString\n",
      "\n",
      "During handling of the above exception, another exception occurred:\n",
      "\n",
      "Traceback (most recent call last):\n",
      "  File \"/usr/lib/spark/python/lib/py4j-0.10.9-src.zip/py4j/java_gateway.py\", line 977, in _get_connection\n",
      "    connection = self.deque.pop()\n",
      "IndexError: pop from an empty deque\n",
      "\n",
      "During handling of the above exception, another exception occurred:\n",
      "\n",
      "Traceback (most recent call last):\n",
      "  File \"/usr/lib/spark/python/lib/py4j-0.10.9-src.zip/py4j/java_gateway.py\", line 1115, in start\n",
      "    self.socket.connect((self.address, self.port))\n",
      "ConnectionRefusedError: [Errno 111] Connection refused\n",
      "ERROR:py4j.java_gateway:An error occurred while trying to connect to the Java server (127.0.0.1:46273)\n",
      "Traceback (most recent call last):\n",
      "  File \"/opt/conda/miniconda3/lib/python3.8/site-packages/IPython/core/interactiveshell.py\", line 3433, in run_code\n",
      "    exec(code_obj, self.user_global_ns, self.user_ns)\n",
      "  File \"/tmp/ipykernel_11737/4115056868.py\", line 1, in <module>\n",
      "    results.join(crypto_df,results.date ==  crypto_df.date,\"left\").show()\n",
      "  File \"/usr/lib/spark/python/pyspark/sql/dataframe.py\", line 484, in show\n",
      "    print(self._jdf.showString(n, 20, vertical))\n",
      "  File \"/usr/lib/spark/python/lib/py4j-0.10.9-src.zip/py4j/java_gateway.py\", line 1304, in __call__\n",
      "    return_value = get_return_value(\n",
      "  File \"/usr/lib/spark/python/pyspark/sql/utils.py\", line 111, in deco\n",
      "    return f(*a, **kw)\n",
      "  File \"/usr/lib/spark/python/lib/py4j-0.10.9-src.zip/py4j/protocol.py\", line 334, in get_return_value\n",
      "    raise Py4JError(\n",
      "py4j.protocol.Py4JError: An error occurred while calling o268.showString\n",
      "\n",
      "During handling of the above exception, another exception occurred:\n",
      "\n",
      "Traceback (most recent call last):\n",
      "  File \"/usr/lib/spark/python/lib/py4j-0.10.9-src.zip/py4j/java_gateway.py\", line 977, in _get_connection\n",
      "    connection = self.deque.pop()\n",
      "IndexError: pop from an empty deque\n",
      "\n",
      "During handling of the above exception, another exception occurred:\n",
      "\n",
      "Traceback (most recent call last):\n",
      "  File \"/usr/lib/spark/python/lib/py4j-0.10.9-src.zip/py4j/java_gateway.py\", line 1115, in start\n",
      "    self.socket.connect((self.address, self.port))\n",
      "ConnectionRefusedError: [Errno 111] Connection refused\n",
      "ERROR:py4j.java_gateway:An error occurred while trying to connect to the Java server (127.0.0.1:46273)\n",
      "Traceback (most recent call last):\n",
      "  File \"/opt/conda/miniconda3/lib/python3.8/site-packages/IPython/core/interactiveshell.py\", line 3433, in run_code\n",
      "    exec(code_obj, self.user_global_ns, self.user_ns)\n",
      "  File \"/tmp/ipykernel_11737/4115056868.py\", line 1, in <module>\n",
      "    results.join(crypto_df,results.date ==  crypto_df.date,\"left\").show()\n",
      "  File \"/usr/lib/spark/python/pyspark/sql/dataframe.py\", line 484, in show\n",
      "    print(self._jdf.showString(n, 20, vertical))\n",
      "  File \"/usr/lib/spark/python/lib/py4j-0.10.9-src.zip/py4j/java_gateway.py\", line 1304, in __call__\n",
      "    return_value = get_return_value(\n",
      "  File \"/usr/lib/spark/python/pyspark/sql/utils.py\", line 111, in deco\n",
      "    return f(*a, **kw)\n",
      "  File \"/usr/lib/spark/python/lib/py4j-0.10.9-src.zip/py4j/protocol.py\", line 334, in get_return_value\n",
      "    raise Py4JError(\n",
      "py4j.protocol.Py4JError: An error occurred while calling o268.showString\n",
      "\n",
      "During handling of the above exception, another exception occurred:\n",
      "\n",
      "Traceback (most recent call last):\n",
      "  File \"/usr/lib/spark/python/lib/py4j-0.10.9-src.zip/py4j/java_gateway.py\", line 977, in _get_connection\n",
      "    connection = self.deque.pop()\n",
      "IndexError: pop from an empty deque\n",
      "\n",
      "During handling of the above exception, another exception occurred:\n",
      "\n",
      "Traceback (most recent call last):\n",
      "  File \"/usr/lib/spark/python/lib/py4j-0.10.9-src.zip/py4j/java_gateway.py\", line 1115, in start\n",
      "    self.socket.connect((self.address, self.port))\n",
      "ConnectionRefusedError: [Errno 111] Connection refused\n",
      "ERROR:py4j.java_gateway:An error occurred while trying to connect to the Java server (127.0.0.1:46273)\n",
      "Traceback (most recent call last):\n",
      "  File \"/opt/conda/miniconda3/lib/python3.8/site-packages/IPython/core/interactiveshell.py\", line 3433, in run_code\n",
      "    exec(code_obj, self.user_global_ns, self.user_ns)\n",
      "  File \"/tmp/ipykernel_11737/4115056868.py\", line 1, in <module>\n",
      "    results.join(crypto_df,results.date ==  crypto_df.date,\"left\").show()\n",
      "  File \"/usr/lib/spark/python/pyspark/sql/dataframe.py\", line 484, in show\n",
      "    print(self._jdf.showString(n, 20, vertical))\n",
      "  File \"/usr/lib/spark/python/lib/py4j-0.10.9-src.zip/py4j/java_gateway.py\", line 1304, in __call__\n",
      "    return_value = get_return_value(\n",
      "  File \"/usr/lib/spark/python/pyspark/sql/utils.py\", line 111, in deco\n",
      "    return f(*a, **kw)\n",
      "  File \"/usr/lib/spark/python/lib/py4j-0.10.9-src.zip/py4j/protocol.py\", line 334, in get_return_value\n",
      "    raise Py4JError(\n",
      "py4j.protocol.Py4JError: An error occurred while calling o268.showString\n",
      "\n",
      "During handling of the above exception, another exception occurred:\n",
      "\n",
      "Traceback (most recent call last):\n",
      "  File \"/usr/lib/spark/python/lib/py4j-0.10.9-src.zip/py4j/java_gateway.py\", line 977, in _get_connection\n",
      "    connection = self.deque.pop()\n",
      "IndexError: pop from an empty deque\n",
      "\n",
      "During handling of the above exception, another exception occurred:\n",
      "\n",
      "Traceback (most recent call last):\n",
      "  File \"/usr/lib/spark/python/lib/py4j-0.10.9-src.zip/py4j/java_gateway.py\", line 1115, in start\n",
      "    self.socket.connect((self.address, self.port))\n",
      "ConnectionRefusedError: [Errno 111] Connection refused\n",
      "ERROR:py4j.java_gateway:An error occurred while trying to connect to the Java server (127.0.0.1:46273)\n",
      "Traceback (most recent call last):\n",
      "  File \"/opt/conda/miniconda3/lib/python3.8/site-packages/IPython/core/interactiveshell.py\", line 3433, in run_code\n",
      "    exec(code_obj, self.user_global_ns, self.user_ns)\n",
      "  File \"/tmp/ipykernel_11737/4115056868.py\", line 1, in <module>\n",
      "    results.join(crypto_df,results.date ==  crypto_df.date,\"left\").show()\n",
      "  File \"/usr/lib/spark/python/pyspark/sql/dataframe.py\", line 484, in show\n",
      "    print(self._jdf.showString(n, 20, vertical))\n",
      "  File \"/usr/lib/spark/python/lib/py4j-0.10.9-src.zip/py4j/java_gateway.py\", line 1304, in __call__\n",
      "    return_value = get_return_value(\n",
      "  File \"/usr/lib/spark/python/pyspark/sql/utils.py\", line 111, in deco\n",
      "    return f(*a, **kw)\n",
      "  File \"/usr/lib/spark/python/lib/py4j-0.10.9-src.zip/py4j/protocol.py\", line 334, in get_return_value\n",
      "    raise Py4JError(\n",
      "py4j.protocol.Py4JError: An error occurred while calling o268.showString\n",
      "\n",
      "During handling of the above exception, another exception occurred:\n",
      "\n",
      "Traceback (most recent call last):\n",
      "  File \"/usr/lib/spark/python/lib/py4j-0.10.9-src.zip/py4j/java_gateway.py\", line 977, in _get_connection\n",
      "    connection = self.deque.pop()\n",
      "IndexError: pop from an empty deque\n",
      "\n",
      "During handling of the above exception, another exception occurred:\n",
      "\n",
      "Traceback (most recent call last):\n",
      "  File \"/usr/lib/spark/python/lib/py4j-0.10.9-src.zip/py4j/java_gateway.py\", line 1115, in start\n",
      "    self.socket.connect((self.address, self.port))\n",
      "ConnectionRefusedError: [Errno 111] Connection refused\n",
      "ERROR:py4j.java_gateway:An error occurred while trying to connect to the Java server (127.0.0.1:46273)\n",
      "Traceback (most recent call last):\n",
      "  File \"/opt/conda/miniconda3/lib/python3.8/site-packages/IPython/core/interactiveshell.py\", line 3433, in run_code\n",
      "    exec(code_obj, self.user_global_ns, self.user_ns)\n",
      "  File \"/tmp/ipykernel_11737/4115056868.py\", line 1, in <module>\n",
      "    results.join(crypto_df,results.date ==  crypto_df.date,\"left\").show()\n",
      "  File \"/usr/lib/spark/python/pyspark/sql/dataframe.py\", line 484, in show\n",
      "    print(self._jdf.showString(n, 20, vertical))\n",
      "  File \"/usr/lib/spark/python/lib/py4j-0.10.9-src.zip/py4j/java_gateway.py\", line 1304, in __call__\n",
      "    return_value = get_return_value(\n",
      "  File \"/usr/lib/spark/python/pyspark/sql/utils.py\", line 111, in deco\n",
      "    return f(*a, **kw)\n",
      "  File \"/usr/lib/spark/python/lib/py4j-0.10.9-src.zip/py4j/protocol.py\", line 334, in get_return_value\n",
      "    raise Py4JError(\n",
      "py4j.protocol.Py4JError: An error occurred while calling o268.showString\n",
      "\n",
      "During handling of the above exception, another exception occurred:\n",
      "\n",
      "Traceback (most recent call last):\n",
      "  File \"/usr/lib/spark/python/lib/py4j-0.10.9-src.zip/py4j/java_gateway.py\", line 977, in _get_connection\n",
      "    connection = self.deque.pop()\n",
      "IndexError: pop from an empty deque\n",
      "\n",
      "During handling of the above exception, another exception occurred:\n",
      "\n",
      "Traceback (most recent call last):\n",
      "  File \"/usr/lib/spark/python/lib/py4j-0.10.9-src.zip/py4j/java_gateway.py\", line 1115, in start\n",
      "    self.socket.connect((self.address, self.port))\n",
      "ConnectionRefusedError: [Errno 111] Connection refused\n"
     ]
    },
    {
     "name": "stderr",
     "output_type": "stream",
     "text": [
      "ERROR:py4j.java_gateway:An error occurred while trying to connect to the Java server (127.0.0.1:46273)\n",
      "Traceback (most recent call last):\n",
      "  File \"/opt/conda/miniconda3/lib/python3.8/site-packages/IPython/core/interactiveshell.py\", line 3433, in run_code\n",
      "    exec(code_obj, self.user_global_ns, self.user_ns)\n",
      "  File \"/tmp/ipykernel_11737/4115056868.py\", line 1, in <module>\n",
      "    results.join(crypto_df,results.date ==  crypto_df.date,\"left\").show()\n",
      "  File \"/usr/lib/spark/python/pyspark/sql/dataframe.py\", line 484, in show\n",
      "    print(self._jdf.showString(n, 20, vertical))\n",
      "  File \"/usr/lib/spark/python/lib/py4j-0.10.9-src.zip/py4j/java_gateway.py\", line 1304, in __call__\n",
      "    return_value = get_return_value(\n",
      "  File \"/usr/lib/spark/python/pyspark/sql/utils.py\", line 111, in deco\n",
      "    return f(*a, **kw)\n",
      "  File \"/usr/lib/spark/python/lib/py4j-0.10.9-src.zip/py4j/protocol.py\", line 334, in get_return_value\n",
      "    raise Py4JError(\n",
      "py4j.protocol.Py4JError: An error occurred while calling o268.showString\n",
      "\n",
      "During handling of the above exception, another exception occurred:\n",
      "\n",
      "Traceback (most recent call last):\n",
      "  File \"/usr/lib/spark/python/lib/py4j-0.10.9-src.zip/py4j/java_gateway.py\", line 977, in _get_connection\n",
      "    connection = self.deque.pop()\n",
      "IndexError: pop from an empty deque\n",
      "\n",
      "During handling of the above exception, another exception occurred:\n",
      "\n",
      "Traceback (most recent call last):\n",
      "  File \"/usr/lib/spark/python/lib/py4j-0.10.9-src.zip/py4j/java_gateway.py\", line 1115, in start\n",
      "    self.socket.connect((self.address, self.port))\n",
      "ConnectionRefusedError: [Errno 111] Connection refused\n",
      "ERROR:py4j.java_gateway:An error occurred while trying to connect to the Java server (127.0.0.1:46273)\n",
      "Traceback (most recent call last):\n",
      "  File \"/opt/conda/miniconda3/lib/python3.8/site-packages/IPython/core/interactiveshell.py\", line 3433, in run_code\n",
      "    exec(code_obj, self.user_global_ns, self.user_ns)\n",
      "  File \"/tmp/ipykernel_11737/4115056868.py\", line 1, in <module>\n",
      "    results.join(crypto_df,results.date ==  crypto_df.date,\"left\").show()\n",
      "  File \"/usr/lib/spark/python/pyspark/sql/dataframe.py\", line 484, in show\n",
      "    print(self._jdf.showString(n, 20, vertical))\n",
      "  File \"/usr/lib/spark/python/lib/py4j-0.10.9-src.zip/py4j/java_gateway.py\", line 1304, in __call__\n",
      "    return_value = get_return_value(\n",
      "  File \"/usr/lib/spark/python/pyspark/sql/utils.py\", line 111, in deco\n",
      "    return f(*a, **kw)\n",
      "  File \"/usr/lib/spark/python/lib/py4j-0.10.9-src.zip/py4j/protocol.py\", line 334, in get_return_value\n",
      "    raise Py4JError(\n",
      "py4j.protocol.Py4JError: An error occurred while calling o268.showString\n",
      "\n",
      "During handling of the above exception, another exception occurred:\n",
      "\n",
      "Traceback (most recent call last):\n",
      "  File \"/usr/lib/spark/python/lib/py4j-0.10.9-src.zip/py4j/java_gateway.py\", line 977, in _get_connection\n",
      "    connection = self.deque.pop()\n",
      "IndexError: pop from an empty deque\n",
      "\n",
      "During handling of the above exception, another exception occurred:\n",
      "\n",
      "Traceback (most recent call last):\n",
      "  File \"/usr/lib/spark/python/lib/py4j-0.10.9-src.zip/py4j/java_gateway.py\", line 1115, in start\n",
      "    self.socket.connect((self.address, self.port))\n",
      "ConnectionRefusedError: [Errno 111] Connection refused\n",
      "ERROR:py4j.java_gateway:An error occurred while trying to connect to the Java server (127.0.0.1:46273)\n",
      "Traceback (most recent call last):\n",
      "  File \"/opt/conda/miniconda3/lib/python3.8/site-packages/IPython/core/interactiveshell.py\", line 3433, in run_code\n",
      "    exec(code_obj, self.user_global_ns, self.user_ns)\n",
      "  File \"/tmp/ipykernel_11737/4115056868.py\", line 1, in <module>\n",
      "    results.join(crypto_df,results.date ==  crypto_df.date,\"left\").show()\n",
      "  File \"/usr/lib/spark/python/pyspark/sql/dataframe.py\", line 484, in show\n",
      "    print(self._jdf.showString(n, 20, vertical))\n",
      "  File \"/usr/lib/spark/python/lib/py4j-0.10.9-src.zip/py4j/java_gateway.py\", line 1304, in __call__\n",
      "    return_value = get_return_value(\n",
      "  File \"/usr/lib/spark/python/pyspark/sql/utils.py\", line 111, in deco\n",
      "    return f(*a, **kw)\n",
      "  File \"/usr/lib/spark/python/lib/py4j-0.10.9-src.zip/py4j/protocol.py\", line 334, in get_return_value\n",
      "    raise Py4JError(\n",
      "py4j.protocol.Py4JError: An error occurred while calling o268.showString\n",
      "\n",
      "During handling of the above exception, another exception occurred:\n",
      "\n",
      "Traceback (most recent call last):\n",
      "  File \"/usr/lib/spark/python/lib/py4j-0.10.9-src.zip/py4j/java_gateway.py\", line 977, in _get_connection\n",
      "    connection = self.deque.pop()\n",
      "IndexError: pop from an empty deque\n",
      "\n",
      "During handling of the above exception, another exception occurred:\n",
      "\n",
      "Traceback (most recent call last):\n",
      "  File \"/usr/lib/spark/python/lib/py4j-0.10.9-src.zip/py4j/java_gateway.py\", line 1115, in start\n",
      "    self.socket.connect((self.address, self.port))\n",
      "ConnectionRefusedError: [Errno 111] Connection refused\n",
      "ERROR:py4j.java_gateway:An error occurred while trying to connect to the Java server (127.0.0.1:46273)\n",
      "Traceback (most recent call last):\n",
      "  File \"/opt/conda/miniconda3/lib/python3.8/site-packages/IPython/core/interactiveshell.py\", line 3433, in run_code\n",
      "    exec(code_obj, self.user_global_ns, self.user_ns)\n",
      "  File \"/tmp/ipykernel_11737/4115056868.py\", line 1, in <module>\n",
      "    results.join(crypto_df,results.date ==  crypto_df.date,\"left\").show()\n",
      "  File \"/usr/lib/spark/python/pyspark/sql/dataframe.py\", line 484, in show\n",
      "    print(self._jdf.showString(n, 20, vertical))\n",
      "  File \"/usr/lib/spark/python/lib/py4j-0.10.9-src.zip/py4j/java_gateway.py\", line 1304, in __call__\n",
      "    return_value = get_return_value(\n",
      "  File \"/usr/lib/spark/python/pyspark/sql/utils.py\", line 111, in deco\n",
      "    return f(*a, **kw)\n",
      "  File \"/usr/lib/spark/python/lib/py4j-0.10.9-src.zip/py4j/protocol.py\", line 334, in get_return_value\n",
      "    raise Py4JError(\n",
      "py4j.protocol.Py4JError: An error occurred while calling o268.showString\n",
      "\n",
      "During handling of the above exception, another exception occurred:\n",
      "\n",
      "Traceback (most recent call last):\n",
      "  File \"/usr/lib/spark/python/lib/py4j-0.10.9-src.zip/py4j/java_gateway.py\", line 977, in _get_connection\n",
      "    connection = self.deque.pop()\n",
      "IndexError: pop from an empty deque\n",
      "\n",
      "During handling of the above exception, another exception occurred:\n",
      "\n",
      "Traceback (most recent call last):\n",
      "  File \"/usr/lib/spark/python/lib/py4j-0.10.9-src.zip/py4j/java_gateway.py\", line 1115, in start\n",
      "    self.socket.connect((self.address, self.port))\n",
      "ConnectionRefusedError: [Errno 111] Connection refused\n",
      "ERROR:py4j.java_gateway:An error occurred while trying to connect to the Java server (127.0.0.1:46273)\n",
      "Traceback (most recent call last):\n",
      "  File \"/opt/conda/miniconda3/lib/python3.8/site-packages/IPython/core/interactiveshell.py\", line 3433, in run_code\n",
      "    exec(code_obj, self.user_global_ns, self.user_ns)\n",
      "  File \"/tmp/ipykernel_11737/4115056868.py\", line 1, in <module>\n",
      "    results.join(crypto_df,results.date ==  crypto_df.date,\"left\").show()\n",
      "  File \"/usr/lib/spark/python/pyspark/sql/dataframe.py\", line 484, in show\n",
      "    print(self._jdf.showString(n, 20, vertical))\n",
      "  File \"/usr/lib/spark/python/lib/py4j-0.10.9-src.zip/py4j/java_gateway.py\", line 1304, in __call__\n",
      "    return_value = get_return_value(\n",
      "  File \"/usr/lib/spark/python/pyspark/sql/utils.py\", line 111, in deco\n",
      "    return f(*a, **kw)\n",
      "  File \"/usr/lib/spark/python/lib/py4j-0.10.9-src.zip/py4j/protocol.py\", line 334, in get_return_value\n",
      "    raise Py4JError(\n",
      "py4j.protocol.Py4JError: An error occurred while calling o268.showString\n",
      "\n",
      "During handling of the above exception, another exception occurred:\n",
      "\n",
      "Traceback (most recent call last):\n",
      "  File \"/usr/lib/spark/python/lib/py4j-0.10.9-src.zip/py4j/java_gateway.py\", line 977, in _get_connection\n",
      "    connection = self.deque.pop()\n",
      "IndexError: pop from an empty deque\n",
      "\n",
      "During handling of the above exception, another exception occurred:\n",
      "\n",
      "Traceback (most recent call last):\n",
      "  File \"/usr/lib/spark/python/lib/py4j-0.10.9-src.zip/py4j/java_gateway.py\", line 1115, in start\n",
      "    self.socket.connect((self.address, self.port))\n",
      "ConnectionRefusedError: [Errno 111] Connection refused\n",
      "ERROR:py4j.java_gateway:An error occurred while trying to connect to the Java server (127.0.0.1:46273)\n",
      "Traceback (most recent call last):\n",
      "  File \"/opt/conda/miniconda3/lib/python3.8/site-packages/IPython/core/interactiveshell.py\", line 3433, in run_code\n",
      "    exec(code_obj, self.user_global_ns, self.user_ns)\n",
      "  File \"/tmp/ipykernel_11737/4115056868.py\", line 1, in <module>\n",
      "    results.join(crypto_df,results.date ==  crypto_df.date,\"left\").show()\n",
      "  File \"/usr/lib/spark/python/pyspark/sql/dataframe.py\", line 484, in show\n",
      "    print(self._jdf.showString(n, 20, vertical))\n",
      "  File \"/usr/lib/spark/python/lib/py4j-0.10.9-src.zip/py4j/java_gateway.py\", line 1304, in __call__\n",
      "    return_value = get_return_value(\n",
      "  File \"/usr/lib/spark/python/pyspark/sql/utils.py\", line 111, in deco\n",
      "    return f(*a, **kw)\n",
      "  File \"/usr/lib/spark/python/lib/py4j-0.10.9-src.zip/py4j/protocol.py\", line 334, in get_return_value\n",
      "    raise Py4JError(\n",
      "py4j.protocol.Py4JError: An error occurred while calling o268.showString\n",
      "\n",
      "During handling of the above exception, another exception occurred:\n",
      "\n",
      "Traceback (most recent call last):\n",
      "  File \"/usr/lib/spark/python/lib/py4j-0.10.9-src.zip/py4j/java_gateway.py\", line 977, in _get_connection\n",
      "    connection = self.deque.pop()\n",
      "IndexError: pop from an empty deque\n",
      "\n",
      "During handling of the above exception, another exception occurred:\n",
      "\n",
      "Traceback (most recent call last):\n",
      "  File \"/usr/lib/spark/python/lib/py4j-0.10.9-src.zip/py4j/java_gateway.py\", line 1115, in start\n",
      "    self.socket.connect((self.address, self.port))\n",
      "ConnectionRefusedError: [Errno 111] Connection refused\n"
     ]
    },
    {
     "name": "stderr",
     "output_type": "stream",
     "text": [
      "ERROR:py4j.java_gateway:An error occurred while trying to connect to the Java server (127.0.0.1:46273)\n",
      "Traceback (most recent call last):\n",
      "  File \"/opt/conda/miniconda3/lib/python3.8/site-packages/IPython/core/interactiveshell.py\", line 3433, in run_code\n",
      "    exec(code_obj, self.user_global_ns, self.user_ns)\n",
      "  File \"/tmp/ipykernel_11737/4115056868.py\", line 1, in <module>\n",
      "    results.join(crypto_df,results.date ==  crypto_df.date,\"left\").show()\n",
      "  File \"/usr/lib/spark/python/pyspark/sql/dataframe.py\", line 484, in show\n",
      "    print(self._jdf.showString(n, 20, vertical))\n",
      "  File \"/usr/lib/spark/python/lib/py4j-0.10.9-src.zip/py4j/java_gateway.py\", line 1304, in __call__\n",
      "    return_value = get_return_value(\n",
      "  File \"/usr/lib/spark/python/pyspark/sql/utils.py\", line 111, in deco\n",
      "    return f(*a, **kw)\n",
      "  File \"/usr/lib/spark/python/lib/py4j-0.10.9-src.zip/py4j/protocol.py\", line 334, in get_return_value\n",
      "    raise Py4JError(\n",
      "py4j.protocol.Py4JError: An error occurred while calling o268.showString\n",
      "\n",
      "During handling of the above exception, another exception occurred:\n",
      "\n",
      "Traceback (most recent call last):\n",
      "  File \"/usr/lib/spark/python/lib/py4j-0.10.9-src.zip/py4j/java_gateway.py\", line 977, in _get_connection\n",
      "    connection = self.deque.pop()\n",
      "IndexError: pop from an empty deque\n",
      "\n",
      "During handling of the above exception, another exception occurred:\n",
      "\n",
      "Traceback (most recent call last):\n",
      "  File \"/usr/lib/spark/python/lib/py4j-0.10.9-src.zip/py4j/java_gateway.py\", line 1115, in start\n",
      "    self.socket.connect((self.address, self.port))\n",
      "ConnectionRefusedError: [Errno 111] Connection refused\n",
      "ERROR:py4j.java_gateway:An error occurred while trying to connect to the Java server (127.0.0.1:46273)\n",
      "Traceback (most recent call last):\n",
      "  File \"/opt/conda/miniconda3/lib/python3.8/site-packages/IPython/core/interactiveshell.py\", line 3433, in run_code\n",
      "    exec(code_obj, self.user_global_ns, self.user_ns)\n",
      "  File \"/tmp/ipykernel_11737/4115056868.py\", line 1, in <module>\n",
      "    results.join(crypto_df,results.date ==  crypto_df.date,\"left\").show()\n",
      "  File \"/usr/lib/spark/python/pyspark/sql/dataframe.py\", line 484, in show\n",
      "    print(self._jdf.showString(n, 20, vertical))\n",
      "  File \"/usr/lib/spark/python/lib/py4j-0.10.9-src.zip/py4j/java_gateway.py\", line 1304, in __call__\n",
      "    return_value = get_return_value(\n",
      "  File \"/usr/lib/spark/python/pyspark/sql/utils.py\", line 111, in deco\n",
      "    return f(*a, **kw)\n",
      "  File \"/usr/lib/spark/python/lib/py4j-0.10.9-src.zip/py4j/protocol.py\", line 334, in get_return_value\n",
      "    raise Py4JError(\n",
      "py4j.protocol.Py4JError: An error occurred while calling o268.showString\n",
      "\n",
      "During handling of the above exception, another exception occurred:\n",
      "\n",
      "Traceback (most recent call last):\n",
      "  File \"/usr/lib/spark/python/lib/py4j-0.10.9-src.zip/py4j/java_gateway.py\", line 977, in _get_connection\n",
      "    connection = self.deque.pop()\n",
      "IndexError: pop from an empty deque\n",
      "\n",
      "During handling of the above exception, another exception occurred:\n",
      "\n",
      "Traceback (most recent call last):\n",
      "  File \"/usr/lib/spark/python/lib/py4j-0.10.9-src.zip/py4j/java_gateway.py\", line 1115, in start\n",
      "    self.socket.connect((self.address, self.port))\n",
      "ConnectionRefusedError: [Errno 111] Connection refused\n",
      "ERROR:py4j.java_gateway:An error occurred while trying to connect to the Java server (127.0.0.1:46273)\n",
      "Traceback (most recent call last):\n",
      "  File \"/opt/conda/miniconda3/lib/python3.8/site-packages/IPython/core/interactiveshell.py\", line 3433, in run_code\n",
      "    exec(code_obj, self.user_global_ns, self.user_ns)\n",
      "  File \"/tmp/ipykernel_11737/4115056868.py\", line 1, in <module>\n",
      "    results.join(crypto_df,results.date ==  crypto_df.date,\"left\").show()\n",
      "  File \"/usr/lib/spark/python/pyspark/sql/dataframe.py\", line 484, in show\n",
      "    print(self._jdf.showString(n, 20, vertical))\n",
      "  File \"/usr/lib/spark/python/lib/py4j-0.10.9-src.zip/py4j/java_gateway.py\", line 1304, in __call__\n",
      "    return_value = get_return_value(\n",
      "  File \"/usr/lib/spark/python/pyspark/sql/utils.py\", line 111, in deco\n",
      "    return f(*a, **kw)\n",
      "  File \"/usr/lib/spark/python/lib/py4j-0.10.9-src.zip/py4j/protocol.py\", line 334, in get_return_value\n",
      "    raise Py4JError(\n",
      "py4j.protocol.Py4JError: An error occurred while calling o268.showString\n",
      "\n",
      "During handling of the above exception, another exception occurred:\n",
      "\n",
      "Traceback (most recent call last):\n",
      "  File \"/usr/lib/spark/python/lib/py4j-0.10.9-src.zip/py4j/java_gateway.py\", line 977, in _get_connection\n",
      "    connection = self.deque.pop()\n",
      "IndexError: pop from an empty deque\n",
      "\n",
      "During handling of the above exception, another exception occurred:\n",
      "\n",
      "Traceback (most recent call last):\n",
      "  File \"/usr/lib/spark/python/lib/py4j-0.10.9-src.zip/py4j/java_gateway.py\", line 1115, in start\n",
      "    self.socket.connect((self.address, self.port))\n",
      "ConnectionRefusedError: [Errno 111] Connection refused\n",
      "ERROR:py4j.java_gateway:An error occurred while trying to connect to the Java server (127.0.0.1:46273)\n",
      "Traceback (most recent call last):\n",
      "  File \"/opt/conda/miniconda3/lib/python3.8/site-packages/IPython/core/interactiveshell.py\", line 3433, in run_code\n",
      "    exec(code_obj, self.user_global_ns, self.user_ns)\n",
      "  File \"/tmp/ipykernel_11737/4115056868.py\", line 1, in <module>\n",
      "    results.join(crypto_df,results.date ==  crypto_df.date,\"left\").show()\n",
      "  File \"/usr/lib/spark/python/pyspark/sql/dataframe.py\", line 484, in show\n",
      "    print(self._jdf.showString(n, 20, vertical))\n",
      "  File \"/usr/lib/spark/python/lib/py4j-0.10.9-src.zip/py4j/java_gateway.py\", line 1304, in __call__\n",
      "    return_value = get_return_value(\n",
      "  File \"/usr/lib/spark/python/pyspark/sql/utils.py\", line 111, in deco\n",
      "    return f(*a, **kw)\n",
      "  File \"/usr/lib/spark/python/lib/py4j-0.10.9-src.zip/py4j/protocol.py\", line 334, in get_return_value\n",
      "    raise Py4JError(\n",
      "py4j.protocol.Py4JError: An error occurred while calling o268.showString\n",
      "\n",
      "During handling of the above exception, another exception occurred:\n",
      "\n",
      "Traceback (most recent call last):\n",
      "  File \"/usr/lib/spark/python/lib/py4j-0.10.9-src.zip/py4j/java_gateway.py\", line 977, in _get_connection\n",
      "    connection = self.deque.pop()\n",
      "IndexError: pop from an empty deque\n",
      "\n",
      "During handling of the above exception, another exception occurred:\n",
      "\n",
      "Traceback (most recent call last):\n",
      "  File \"/usr/lib/spark/python/lib/py4j-0.10.9-src.zip/py4j/java_gateway.py\", line 1115, in start\n",
      "    self.socket.connect((self.address, self.port))\n",
      "ConnectionRefusedError: [Errno 111] Connection refused\n",
      "ERROR:py4j.java_gateway:An error occurred while trying to connect to the Java server (127.0.0.1:46273)\n",
      "Traceback (most recent call last):\n",
      "  File \"/opt/conda/miniconda3/lib/python3.8/site-packages/IPython/core/interactiveshell.py\", line 3433, in run_code\n",
      "    exec(code_obj, self.user_global_ns, self.user_ns)\n",
      "  File \"/tmp/ipykernel_11737/4115056868.py\", line 1, in <module>\n",
      "    results.join(crypto_df,results.date ==  crypto_df.date,\"left\").show()\n",
      "  File \"/usr/lib/spark/python/pyspark/sql/dataframe.py\", line 484, in show\n",
      "    print(self._jdf.showString(n, 20, vertical))\n",
      "  File \"/usr/lib/spark/python/lib/py4j-0.10.9-src.zip/py4j/java_gateway.py\", line 1304, in __call__\n",
      "    return_value = get_return_value(\n",
      "  File \"/usr/lib/spark/python/pyspark/sql/utils.py\", line 111, in deco\n",
      "    return f(*a, **kw)\n",
      "  File \"/usr/lib/spark/python/lib/py4j-0.10.9-src.zip/py4j/protocol.py\", line 334, in get_return_value\n",
      "    raise Py4JError(\n",
      "py4j.protocol.Py4JError: An error occurred while calling o268.showString\n",
      "\n",
      "During handling of the above exception, another exception occurred:\n",
      "\n",
      "Traceback (most recent call last):\n",
      "  File \"/usr/lib/spark/python/lib/py4j-0.10.9-src.zip/py4j/java_gateway.py\", line 977, in _get_connection\n",
      "    connection = self.deque.pop()\n",
      "IndexError: pop from an empty deque\n",
      "\n",
      "During handling of the above exception, another exception occurred:\n",
      "\n",
      "Traceback (most recent call last):\n",
      "  File \"/usr/lib/spark/python/lib/py4j-0.10.9-src.zip/py4j/java_gateway.py\", line 1115, in start\n",
      "    self.socket.connect((self.address, self.port))\n",
      "ConnectionRefusedError: [Errno 111] Connection refused\n",
      "ERROR:py4j.java_gateway:An error occurred while trying to connect to the Java server (127.0.0.1:46273)\n",
      "Traceback (most recent call last):\n",
      "  File \"/opt/conda/miniconda3/lib/python3.8/site-packages/IPython/core/interactiveshell.py\", line 3433, in run_code\n",
      "    exec(code_obj, self.user_global_ns, self.user_ns)\n",
      "  File \"/tmp/ipykernel_11737/4115056868.py\", line 1, in <module>\n",
      "    results.join(crypto_df,results.date ==  crypto_df.date,\"left\").show()\n",
      "  File \"/usr/lib/spark/python/pyspark/sql/dataframe.py\", line 484, in show\n",
      "    print(self._jdf.showString(n, 20, vertical))\n",
      "  File \"/usr/lib/spark/python/lib/py4j-0.10.9-src.zip/py4j/java_gateway.py\", line 1304, in __call__\n",
      "    return_value = get_return_value(\n",
      "  File \"/usr/lib/spark/python/pyspark/sql/utils.py\", line 111, in deco\n",
      "    return f(*a, **kw)\n",
      "  File \"/usr/lib/spark/python/lib/py4j-0.10.9-src.zip/py4j/protocol.py\", line 334, in get_return_value\n",
      "    raise Py4JError(\n",
      "py4j.protocol.Py4JError: An error occurred while calling o268.showString\n",
      "\n",
      "During handling of the above exception, another exception occurred:\n",
      "\n",
      "Traceback (most recent call last):\n",
      "  File \"/usr/lib/spark/python/lib/py4j-0.10.9-src.zip/py4j/java_gateway.py\", line 977, in _get_connection\n",
      "    connection = self.deque.pop()\n",
      "IndexError: pop from an empty deque\n",
      "\n",
      "During handling of the above exception, another exception occurred:\n",
      "\n",
      "Traceback (most recent call last):\n",
      "  File \"/usr/lib/spark/python/lib/py4j-0.10.9-src.zip/py4j/java_gateway.py\", line 1115, in start\n",
      "    self.socket.connect((self.address, self.port))\n",
      "ConnectionRefusedError: [Errno 111] Connection refused\n"
     ]
    },
    {
     "name": "stderr",
     "output_type": "stream",
     "text": [
      "ERROR:py4j.java_gateway:An error occurred while trying to connect to the Java server (127.0.0.1:46273)\n",
      "Traceback (most recent call last):\n",
      "  File \"/opt/conda/miniconda3/lib/python3.8/site-packages/IPython/core/interactiveshell.py\", line 3433, in run_code\n",
      "    exec(code_obj, self.user_global_ns, self.user_ns)\n",
      "  File \"/tmp/ipykernel_11737/4115056868.py\", line 1, in <module>\n",
      "    results.join(crypto_df,results.date ==  crypto_df.date,\"left\").show()\n",
      "  File \"/usr/lib/spark/python/pyspark/sql/dataframe.py\", line 484, in show\n",
      "    print(self._jdf.showString(n, 20, vertical))\n",
      "  File \"/usr/lib/spark/python/lib/py4j-0.10.9-src.zip/py4j/java_gateway.py\", line 1304, in __call__\n",
      "    return_value = get_return_value(\n",
      "  File \"/usr/lib/spark/python/pyspark/sql/utils.py\", line 111, in deco\n",
      "    return f(*a, **kw)\n",
      "  File \"/usr/lib/spark/python/lib/py4j-0.10.9-src.zip/py4j/protocol.py\", line 334, in get_return_value\n",
      "    raise Py4JError(\n",
      "py4j.protocol.Py4JError: An error occurred while calling o268.showString\n",
      "\n",
      "During handling of the above exception, another exception occurred:\n",
      "\n",
      "Traceback (most recent call last):\n",
      "  File \"/usr/lib/spark/python/lib/py4j-0.10.9-src.zip/py4j/java_gateway.py\", line 977, in _get_connection\n",
      "    connection = self.deque.pop()\n",
      "IndexError: pop from an empty deque\n",
      "\n",
      "During handling of the above exception, another exception occurred:\n",
      "\n",
      "Traceback (most recent call last):\n",
      "  File \"/usr/lib/spark/python/lib/py4j-0.10.9-src.zip/py4j/java_gateway.py\", line 1115, in start\n",
      "    self.socket.connect((self.address, self.port))\n",
      "ConnectionRefusedError: [Errno 111] Connection refused\n",
      "ERROR:py4j.java_gateway:An error occurred while trying to connect to the Java server (127.0.0.1:46273)\n",
      "Traceback (most recent call last):\n",
      "  File \"/opt/conda/miniconda3/lib/python3.8/site-packages/IPython/core/interactiveshell.py\", line 3433, in run_code\n",
      "    exec(code_obj, self.user_global_ns, self.user_ns)\n",
      "  File \"/tmp/ipykernel_11737/4115056868.py\", line 1, in <module>\n",
      "    results.join(crypto_df,results.date ==  crypto_df.date,\"left\").show()\n",
      "  File \"/usr/lib/spark/python/pyspark/sql/dataframe.py\", line 484, in show\n",
      "    print(self._jdf.showString(n, 20, vertical))\n",
      "  File \"/usr/lib/spark/python/lib/py4j-0.10.9-src.zip/py4j/java_gateway.py\", line 1304, in __call__\n",
      "    return_value = get_return_value(\n",
      "  File \"/usr/lib/spark/python/pyspark/sql/utils.py\", line 111, in deco\n",
      "    return f(*a, **kw)\n",
      "  File \"/usr/lib/spark/python/lib/py4j-0.10.9-src.zip/py4j/protocol.py\", line 334, in get_return_value\n",
      "    raise Py4JError(\n",
      "py4j.protocol.Py4JError: An error occurred while calling o268.showString\n",
      "\n",
      "During handling of the above exception, another exception occurred:\n",
      "\n",
      "Traceback (most recent call last):\n",
      "  File \"/usr/lib/spark/python/lib/py4j-0.10.9-src.zip/py4j/java_gateway.py\", line 977, in _get_connection\n",
      "    connection = self.deque.pop()\n",
      "IndexError: pop from an empty deque\n",
      "\n",
      "During handling of the above exception, another exception occurred:\n",
      "\n",
      "Traceback (most recent call last):\n",
      "  File \"/usr/lib/spark/python/lib/py4j-0.10.9-src.zip/py4j/java_gateway.py\", line 1115, in start\n",
      "    self.socket.connect((self.address, self.port))\n",
      "ConnectionRefusedError: [Errno 111] Connection refused\n",
      "ERROR:py4j.java_gateway:An error occurred while trying to connect to the Java server (127.0.0.1:46273)\n",
      "Traceback (most recent call last):\n",
      "  File \"/opt/conda/miniconda3/lib/python3.8/site-packages/IPython/core/interactiveshell.py\", line 3433, in run_code\n",
      "    exec(code_obj, self.user_global_ns, self.user_ns)\n",
      "  File \"/tmp/ipykernel_11737/4115056868.py\", line 1, in <module>\n",
      "    results.join(crypto_df,results.date ==  crypto_df.date,\"left\").show()\n",
      "  File \"/usr/lib/spark/python/pyspark/sql/dataframe.py\", line 484, in show\n",
      "    print(self._jdf.showString(n, 20, vertical))\n",
      "  File \"/usr/lib/spark/python/lib/py4j-0.10.9-src.zip/py4j/java_gateway.py\", line 1304, in __call__\n",
      "    return_value = get_return_value(\n",
      "  File \"/usr/lib/spark/python/pyspark/sql/utils.py\", line 111, in deco\n",
      "    return f(*a, **kw)\n",
      "  File \"/usr/lib/spark/python/lib/py4j-0.10.9-src.zip/py4j/protocol.py\", line 334, in get_return_value\n",
      "    raise Py4JError(\n",
      "py4j.protocol.Py4JError: An error occurred while calling o268.showString\n",
      "\n",
      "During handling of the above exception, another exception occurred:\n",
      "\n",
      "Traceback (most recent call last):\n",
      "  File \"/usr/lib/spark/python/lib/py4j-0.10.9-src.zip/py4j/java_gateway.py\", line 977, in _get_connection\n",
      "    connection = self.deque.pop()\n",
      "IndexError: pop from an empty deque\n",
      "\n",
      "During handling of the above exception, another exception occurred:\n",
      "\n",
      "Traceback (most recent call last):\n",
      "  File \"/usr/lib/spark/python/lib/py4j-0.10.9-src.zip/py4j/java_gateway.py\", line 1115, in start\n",
      "    self.socket.connect((self.address, self.port))\n",
      "ConnectionRefusedError: [Errno 111] Connection refused\n",
      "ERROR:py4j.java_gateway:An error occurred while trying to connect to the Java server (127.0.0.1:46273)\n",
      "Traceback (most recent call last):\n",
      "  File \"/opt/conda/miniconda3/lib/python3.8/site-packages/IPython/core/interactiveshell.py\", line 3433, in run_code\n",
      "    exec(code_obj, self.user_global_ns, self.user_ns)\n",
      "  File \"/tmp/ipykernel_11737/4115056868.py\", line 1, in <module>\n",
      "    results.join(crypto_df,results.date ==  crypto_df.date,\"left\").show()\n",
      "  File \"/usr/lib/spark/python/pyspark/sql/dataframe.py\", line 484, in show\n",
      "    print(self._jdf.showString(n, 20, vertical))\n",
      "  File \"/usr/lib/spark/python/lib/py4j-0.10.9-src.zip/py4j/java_gateway.py\", line 1304, in __call__\n",
      "    return_value = get_return_value(\n",
      "  File \"/usr/lib/spark/python/pyspark/sql/utils.py\", line 111, in deco\n",
      "    return f(*a, **kw)\n",
      "  File \"/usr/lib/spark/python/lib/py4j-0.10.9-src.zip/py4j/protocol.py\", line 334, in get_return_value\n",
      "    raise Py4JError(\n",
      "py4j.protocol.Py4JError: An error occurred while calling o268.showString\n",
      "\n",
      "During handling of the above exception, another exception occurred:\n",
      "\n",
      "Traceback (most recent call last):\n",
      "  File \"/usr/lib/spark/python/lib/py4j-0.10.9-src.zip/py4j/java_gateway.py\", line 977, in _get_connection\n",
      "    connection = self.deque.pop()\n",
      "IndexError: pop from an empty deque\n",
      "\n",
      "During handling of the above exception, another exception occurred:\n",
      "\n",
      "Traceback (most recent call last):\n",
      "  File \"/usr/lib/spark/python/lib/py4j-0.10.9-src.zip/py4j/java_gateway.py\", line 1115, in start\n",
      "    self.socket.connect((self.address, self.port))\n",
      "ConnectionRefusedError: [Errno 111] Connection refused\n",
      "ERROR:py4j.java_gateway:An error occurred while trying to connect to the Java server (127.0.0.1:46273)\n",
      "Traceback (most recent call last):\n",
      "  File \"/opt/conda/miniconda3/lib/python3.8/site-packages/IPython/core/interactiveshell.py\", line 3433, in run_code\n",
      "    exec(code_obj, self.user_global_ns, self.user_ns)\n",
      "  File \"/tmp/ipykernel_11737/4115056868.py\", line 1, in <module>\n",
      "    results.join(crypto_df,results.date ==  crypto_df.date,\"left\").show()\n",
      "  File \"/usr/lib/spark/python/pyspark/sql/dataframe.py\", line 484, in show\n",
      "    print(self._jdf.showString(n, 20, vertical))\n",
      "  File \"/usr/lib/spark/python/lib/py4j-0.10.9-src.zip/py4j/java_gateway.py\", line 1304, in __call__\n",
      "    return_value = get_return_value(\n",
      "  File \"/usr/lib/spark/python/pyspark/sql/utils.py\", line 111, in deco\n",
      "    return f(*a, **kw)\n",
      "  File \"/usr/lib/spark/python/lib/py4j-0.10.9-src.zip/py4j/protocol.py\", line 334, in get_return_value\n",
      "    raise Py4JError(\n",
      "py4j.protocol.Py4JError: An error occurred while calling o268.showString\n",
      "\n",
      "During handling of the above exception, another exception occurred:\n",
      "\n",
      "Traceback (most recent call last):\n",
      "  File \"/usr/lib/spark/python/lib/py4j-0.10.9-src.zip/py4j/java_gateway.py\", line 977, in _get_connection\n",
      "    connection = self.deque.pop()\n",
      "IndexError: pop from an empty deque\n",
      "\n",
      "During handling of the above exception, another exception occurred:\n",
      "\n",
      "Traceback (most recent call last):\n",
      "  File \"/usr/lib/spark/python/lib/py4j-0.10.9-src.zip/py4j/java_gateway.py\", line 1115, in start\n",
      "    self.socket.connect((self.address, self.port))\n",
      "ConnectionRefusedError: [Errno 111] Connection refused\n",
      "ERROR:py4j.java_gateway:An error occurred while trying to connect to the Java server (127.0.0.1:46273)\n",
      "Traceback (most recent call last):\n",
      "  File \"/opt/conda/miniconda3/lib/python3.8/site-packages/IPython/core/interactiveshell.py\", line 3433, in run_code\n",
      "    exec(code_obj, self.user_global_ns, self.user_ns)\n",
      "  File \"/tmp/ipykernel_11737/4115056868.py\", line 1, in <module>\n",
      "    results.join(crypto_df,results.date ==  crypto_df.date,\"left\").show()\n",
      "  File \"/usr/lib/spark/python/pyspark/sql/dataframe.py\", line 484, in show\n",
      "    print(self._jdf.showString(n, 20, vertical))\n",
      "  File \"/usr/lib/spark/python/lib/py4j-0.10.9-src.zip/py4j/java_gateway.py\", line 1304, in __call__\n",
      "    return_value = get_return_value(\n",
      "  File \"/usr/lib/spark/python/pyspark/sql/utils.py\", line 111, in deco\n",
      "    return f(*a, **kw)\n",
      "  File \"/usr/lib/spark/python/lib/py4j-0.10.9-src.zip/py4j/protocol.py\", line 334, in get_return_value\n",
      "    raise Py4JError(\n",
      "py4j.protocol.Py4JError: An error occurred while calling o268.showString\n",
      "\n",
      "During handling of the above exception, another exception occurred:\n",
      "\n",
      "Traceback (most recent call last):\n",
      "  File \"/usr/lib/spark/python/lib/py4j-0.10.9-src.zip/py4j/java_gateway.py\", line 977, in _get_connection\n",
      "    connection = self.deque.pop()\n",
      "IndexError: pop from an empty deque\n",
      "\n",
      "During handling of the above exception, another exception occurred:\n",
      "\n",
      "Traceback (most recent call last):\n",
      "  File \"/usr/lib/spark/python/lib/py4j-0.10.9-src.zip/py4j/java_gateway.py\", line 1115, in start\n",
      "    self.socket.connect((self.address, self.port))\n",
      "ConnectionRefusedError: [Errno 111] Connection refused\n"
     ]
    },
    {
     "name": "stderr",
     "output_type": "stream",
     "text": [
      "ERROR:py4j.java_gateway:An error occurred while trying to connect to the Java server (127.0.0.1:46273)\n",
      "Traceback (most recent call last):\n",
      "  File \"/opt/conda/miniconda3/lib/python3.8/site-packages/IPython/core/interactiveshell.py\", line 3433, in run_code\n",
      "    exec(code_obj, self.user_global_ns, self.user_ns)\n",
      "  File \"/tmp/ipykernel_11737/4115056868.py\", line 1, in <module>\n",
      "    results.join(crypto_df,results.date ==  crypto_df.date,\"left\").show()\n",
      "  File \"/usr/lib/spark/python/pyspark/sql/dataframe.py\", line 484, in show\n",
      "    print(self._jdf.showString(n, 20, vertical))\n",
      "  File \"/usr/lib/spark/python/lib/py4j-0.10.9-src.zip/py4j/java_gateway.py\", line 1304, in __call__\n",
      "    return_value = get_return_value(\n",
      "  File \"/usr/lib/spark/python/pyspark/sql/utils.py\", line 111, in deco\n",
      "    return f(*a, **kw)\n",
      "  File \"/usr/lib/spark/python/lib/py4j-0.10.9-src.zip/py4j/protocol.py\", line 334, in get_return_value\n",
      "    raise Py4JError(\n",
      "py4j.protocol.Py4JError: An error occurred while calling o268.showString\n",
      "\n",
      "During handling of the above exception, another exception occurred:\n",
      "\n",
      "Traceback (most recent call last):\n",
      "  File \"/usr/lib/spark/python/lib/py4j-0.10.9-src.zip/py4j/java_gateway.py\", line 977, in _get_connection\n",
      "    connection = self.deque.pop()\n",
      "IndexError: pop from an empty deque\n",
      "\n",
      "During handling of the above exception, another exception occurred:\n",
      "\n",
      "Traceback (most recent call last):\n",
      "  File \"/usr/lib/spark/python/lib/py4j-0.10.9-src.zip/py4j/java_gateway.py\", line 1115, in start\n",
      "    self.socket.connect((self.address, self.port))\n",
      "ConnectionRefusedError: [Errno 111] Connection refused\n",
      "ERROR:py4j.java_gateway:An error occurred while trying to connect to the Java server (127.0.0.1:46273)\n",
      "Traceback (most recent call last):\n",
      "  File \"/opt/conda/miniconda3/lib/python3.8/site-packages/IPython/core/interactiveshell.py\", line 3433, in run_code\n",
      "    exec(code_obj, self.user_global_ns, self.user_ns)\n",
      "  File \"/tmp/ipykernel_11737/4115056868.py\", line 1, in <module>\n",
      "    results.join(crypto_df,results.date ==  crypto_df.date,\"left\").show()\n",
      "  File \"/usr/lib/spark/python/pyspark/sql/dataframe.py\", line 484, in show\n",
      "    print(self._jdf.showString(n, 20, vertical))\n",
      "  File \"/usr/lib/spark/python/lib/py4j-0.10.9-src.zip/py4j/java_gateway.py\", line 1304, in __call__\n",
      "    return_value = get_return_value(\n",
      "  File \"/usr/lib/spark/python/pyspark/sql/utils.py\", line 111, in deco\n",
      "    return f(*a, **kw)\n",
      "  File \"/usr/lib/spark/python/lib/py4j-0.10.9-src.zip/py4j/protocol.py\", line 334, in get_return_value\n",
      "    raise Py4JError(\n",
      "py4j.protocol.Py4JError: An error occurred while calling o268.showString\n",
      "\n",
      "During handling of the above exception, another exception occurred:\n",
      "\n",
      "Traceback (most recent call last):\n",
      "  File \"/usr/lib/spark/python/lib/py4j-0.10.9-src.zip/py4j/java_gateway.py\", line 977, in _get_connection\n",
      "    connection = self.deque.pop()\n",
      "IndexError: pop from an empty deque\n",
      "\n",
      "During handling of the above exception, another exception occurred:\n",
      "\n",
      "Traceback (most recent call last):\n",
      "  File \"/usr/lib/spark/python/lib/py4j-0.10.9-src.zip/py4j/java_gateway.py\", line 1115, in start\n",
      "    self.socket.connect((self.address, self.port))\n",
      "ConnectionRefusedError: [Errno 111] Connection refused\n",
      "ERROR:py4j.java_gateway:An error occurred while trying to connect to the Java server (127.0.0.1:46273)\n",
      "Traceback (most recent call last):\n",
      "  File \"/opt/conda/miniconda3/lib/python3.8/site-packages/IPython/core/interactiveshell.py\", line 3433, in run_code\n",
      "    exec(code_obj, self.user_global_ns, self.user_ns)\n",
      "  File \"/tmp/ipykernel_11737/4115056868.py\", line 1, in <module>\n",
      "    results.join(crypto_df,results.date ==  crypto_df.date,\"left\").show()\n",
      "  File \"/usr/lib/spark/python/pyspark/sql/dataframe.py\", line 484, in show\n",
      "    print(self._jdf.showString(n, 20, vertical))\n",
      "  File \"/usr/lib/spark/python/lib/py4j-0.10.9-src.zip/py4j/java_gateway.py\", line 1304, in __call__\n",
      "    return_value = get_return_value(\n",
      "  File \"/usr/lib/spark/python/pyspark/sql/utils.py\", line 111, in deco\n",
      "    return f(*a, **kw)\n",
      "  File \"/usr/lib/spark/python/lib/py4j-0.10.9-src.zip/py4j/protocol.py\", line 334, in get_return_value\n",
      "    raise Py4JError(\n",
      "py4j.protocol.Py4JError: An error occurred while calling o268.showString\n",
      "\n",
      "During handling of the above exception, another exception occurred:\n",
      "\n",
      "Traceback (most recent call last):\n",
      "  File \"/usr/lib/spark/python/lib/py4j-0.10.9-src.zip/py4j/java_gateway.py\", line 977, in _get_connection\n",
      "    connection = self.deque.pop()\n",
      "IndexError: pop from an empty deque\n",
      "\n",
      "During handling of the above exception, another exception occurred:\n",
      "\n",
      "Traceback (most recent call last):\n",
      "  File \"/usr/lib/spark/python/lib/py4j-0.10.9-src.zip/py4j/java_gateway.py\", line 1115, in start\n",
      "    self.socket.connect((self.address, self.port))\n",
      "ConnectionRefusedError: [Errno 111] Connection refused\n",
      "ERROR:py4j.java_gateway:An error occurred while trying to connect to the Java server (127.0.0.1:46273)\n",
      "Traceback (most recent call last):\n",
      "  File \"/opt/conda/miniconda3/lib/python3.8/site-packages/IPython/core/interactiveshell.py\", line 3433, in run_code\n",
      "    exec(code_obj, self.user_global_ns, self.user_ns)\n",
      "  File \"/tmp/ipykernel_11737/4115056868.py\", line 1, in <module>\n",
      "    results.join(crypto_df,results.date ==  crypto_df.date,\"left\").show()\n",
      "  File \"/usr/lib/spark/python/pyspark/sql/dataframe.py\", line 484, in show\n",
      "    print(self._jdf.showString(n, 20, vertical))\n",
      "  File \"/usr/lib/spark/python/lib/py4j-0.10.9-src.zip/py4j/java_gateway.py\", line 1304, in __call__\n",
      "    return_value = get_return_value(\n",
      "  File \"/usr/lib/spark/python/pyspark/sql/utils.py\", line 111, in deco\n",
      "    return f(*a, **kw)\n",
      "  File \"/usr/lib/spark/python/lib/py4j-0.10.9-src.zip/py4j/protocol.py\", line 334, in get_return_value\n",
      "    raise Py4JError(\n",
      "py4j.protocol.Py4JError: An error occurred while calling o268.showString\n",
      "\n",
      "During handling of the above exception, another exception occurred:\n",
      "\n",
      "Traceback (most recent call last):\n",
      "  File \"/usr/lib/spark/python/lib/py4j-0.10.9-src.zip/py4j/java_gateway.py\", line 977, in _get_connection\n",
      "    connection = self.deque.pop()\n",
      "IndexError: pop from an empty deque\n",
      "\n",
      "During handling of the above exception, another exception occurred:\n",
      "\n",
      "Traceback (most recent call last):\n",
      "  File \"/usr/lib/spark/python/lib/py4j-0.10.9-src.zip/py4j/java_gateway.py\", line 1115, in start\n",
      "    self.socket.connect((self.address, self.port))\n",
      "ConnectionRefusedError: [Errno 111] Connection refused\n",
      "ERROR:py4j.java_gateway:An error occurred while trying to connect to the Java server (127.0.0.1:46273)\n",
      "Traceback (most recent call last):\n",
      "  File \"/opt/conda/miniconda3/lib/python3.8/site-packages/IPython/core/interactiveshell.py\", line 3433, in run_code\n",
      "    exec(code_obj, self.user_global_ns, self.user_ns)\n",
      "  File \"/tmp/ipykernel_11737/4115056868.py\", line 1, in <module>\n",
      "    results.join(crypto_df,results.date ==  crypto_df.date,\"left\").show()\n",
      "  File \"/usr/lib/spark/python/pyspark/sql/dataframe.py\", line 484, in show\n",
      "    print(self._jdf.showString(n, 20, vertical))\n",
      "  File \"/usr/lib/spark/python/lib/py4j-0.10.9-src.zip/py4j/java_gateway.py\", line 1304, in __call__\n",
      "    return_value = get_return_value(\n",
      "  File \"/usr/lib/spark/python/pyspark/sql/utils.py\", line 111, in deco\n",
      "    return f(*a, **kw)\n",
      "  File \"/usr/lib/spark/python/lib/py4j-0.10.9-src.zip/py4j/protocol.py\", line 334, in get_return_value\n",
      "    raise Py4JError(\n",
      "py4j.protocol.Py4JError: An error occurred while calling o268.showString\n",
      "\n",
      "During handling of the above exception, another exception occurred:\n",
      "\n",
      "Traceback (most recent call last):\n",
      "  File \"/usr/lib/spark/python/lib/py4j-0.10.9-src.zip/py4j/java_gateway.py\", line 977, in _get_connection\n",
      "    connection = self.deque.pop()\n",
      "IndexError: pop from an empty deque\n",
      "\n",
      "During handling of the above exception, another exception occurred:\n",
      "\n",
      "Traceback (most recent call last):\n",
      "  File \"/usr/lib/spark/python/lib/py4j-0.10.9-src.zip/py4j/java_gateway.py\", line 1115, in start\n",
      "    self.socket.connect((self.address, self.port))\n",
      "ConnectionRefusedError: [Errno 111] Connection refused\n",
      "ERROR:py4j.java_gateway:An error occurred while trying to connect to the Java server (127.0.0.1:46273)\n",
      "Traceback (most recent call last):\n",
      "  File \"/opt/conda/miniconda3/lib/python3.8/site-packages/IPython/core/interactiveshell.py\", line 3433, in run_code\n",
      "    exec(code_obj, self.user_global_ns, self.user_ns)\n",
      "  File \"/tmp/ipykernel_11737/4115056868.py\", line 1, in <module>\n",
      "    results.join(crypto_df,results.date ==  crypto_df.date,\"left\").show()\n",
      "  File \"/usr/lib/spark/python/pyspark/sql/dataframe.py\", line 484, in show\n",
      "    print(self._jdf.showString(n, 20, vertical))\n",
      "  File \"/usr/lib/spark/python/lib/py4j-0.10.9-src.zip/py4j/java_gateway.py\", line 1304, in __call__\n",
      "    return_value = get_return_value(\n",
      "  File \"/usr/lib/spark/python/pyspark/sql/utils.py\", line 111, in deco\n",
      "    return f(*a, **kw)\n",
      "  File \"/usr/lib/spark/python/lib/py4j-0.10.9-src.zip/py4j/protocol.py\", line 334, in get_return_value\n",
      "    raise Py4JError(\n",
      "py4j.protocol.Py4JError: An error occurred while calling o268.showString\n",
      "\n",
      "During handling of the above exception, another exception occurred:\n",
      "\n",
      "Traceback (most recent call last):\n",
      "  File \"/usr/lib/spark/python/lib/py4j-0.10.9-src.zip/py4j/java_gateway.py\", line 977, in _get_connection\n",
      "    connection = self.deque.pop()\n",
      "IndexError: pop from an empty deque\n",
      "\n",
      "During handling of the above exception, another exception occurred:\n",
      "\n",
      "Traceback (most recent call last):\n",
      "  File \"/usr/lib/spark/python/lib/py4j-0.10.9-src.zip/py4j/java_gateway.py\", line 1115, in start\n",
      "    self.socket.connect((self.address, self.port))\n",
      "ConnectionRefusedError: [Errno 111] Connection refused\n"
     ]
    },
    {
     "name": "stderr",
     "output_type": "stream",
     "text": [
      "ERROR:py4j.java_gateway:An error occurred while trying to connect to the Java server (127.0.0.1:46273)\n",
      "Traceback (most recent call last):\n",
      "  File \"/opt/conda/miniconda3/lib/python3.8/site-packages/IPython/core/interactiveshell.py\", line 3433, in run_code\n",
      "    exec(code_obj, self.user_global_ns, self.user_ns)\n",
      "  File \"/tmp/ipykernel_11737/4115056868.py\", line 1, in <module>\n",
      "    results.join(crypto_df,results.date ==  crypto_df.date,\"left\").show()\n",
      "  File \"/usr/lib/spark/python/pyspark/sql/dataframe.py\", line 484, in show\n",
      "    print(self._jdf.showString(n, 20, vertical))\n",
      "  File \"/usr/lib/spark/python/lib/py4j-0.10.9-src.zip/py4j/java_gateway.py\", line 1304, in __call__\n",
      "    return_value = get_return_value(\n",
      "  File \"/usr/lib/spark/python/pyspark/sql/utils.py\", line 111, in deco\n",
      "    return f(*a, **kw)\n",
      "  File \"/usr/lib/spark/python/lib/py4j-0.10.9-src.zip/py4j/protocol.py\", line 334, in get_return_value\n",
      "    raise Py4JError(\n",
      "py4j.protocol.Py4JError: An error occurred while calling o268.showString\n",
      "\n",
      "During handling of the above exception, another exception occurred:\n",
      "\n",
      "Traceback (most recent call last):\n",
      "  File \"/usr/lib/spark/python/lib/py4j-0.10.9-src.zip/py4j/java_gateway.py\", line 977, in _get_connection\n",
      "    connection = self.deque.pop()\n",
      "IndexError: pop from an empty deque\n",
      "\n",
      "During handling of the above exception, another exception occurred:\n",
      "\n",
      "Traceback (most recent call last):\n",
      "  File \"/usr/lib/spark/python/lib/py4j-0.10.9-src.zip/py4j/java_gateway.py\", line 1115, in start\n",
      "    self.socket.connect((self.address, self.port))\n",
      "ConnectionRefusedError: [Errno 111] Connection refused\n",
      "ERROR:py4j.java_gateway:An error occurred while trying to connect to the Java server (127.0.0.1:46273)\n",
      "Traceback (most recent call last):\n",
      "  File \"/opt/conda/miniconda3/lib/python3.8/site-packages/IPython/core/interactiveshell.py\", line 3433, in run_code\n",
      "    exec(code_obj, self.user_global_ns, self.user_ns)\n",
      "  File \"/tmp/ipykernel_11737/4115056868.py\", line 1, in <module>\n",
      "    results.join(crypto_df,results.date ==  crypto_df.date,\"left\").show()\n",
      "  File \"/usr/lib/spark/python/pyspark/sql/dataframe.py\", line 484, in show\n",
      "    print(self._jdf.showString(n, 20, vertical))\n",
      "  File \"/usr/lib/spark/python/lib/py4j-0.10.9-src.zip/py4j/java_gateway.py\", line 1304, in __call__\n",
      "    return_value = get_return_value(\n",
      "  File \"/usr/lib/spark/python/pyspark/sql/utils.py\", line 111, in deco\n",
      "    return f(*a, **kw)\n",
      "  File \"/usr/lib/spark/python/lib/py4j-0.10.9-src.zip/py4j/protocol.py\", line 334, in get_return_value\n",
      "    raise Py4JError(\n",
      "py4j.protocol.Py4JError: An error occurred while calling o268.showString\n",
      "\n",
      "During handling of the above exception, another exception occurred:\n",
      "\n",
      "Traceback (most recent call last):\n",
      "  File \"/usr/lib/spark/python/lib/py4j-0.10.9-src.zip/py4j/java_gateway.py\", line 977, in _get_connection\n",
      "    connection = self.deque.pop()\n",
      "IndexError: pop from an empty deque\n",
      "\n",
      "During handling of the above exception, another exception occurred:\n",
      "\n",
      "Traceback (most recent call last):\n",
      "  File \"/usr/lib/spark/python/lib/py4j-0.10.9-src.zip/py4j/java_gateway.py\", line 1115, in start\n",
      "    self.socket.connect((self.address, self.port))\n",
      "ConnectionRefusedError: [Errno 111] Connection refused\n",
      "ERROR:py4j.java_gateway:An error occurred while trying to connect to the Java server (127.0.0.1:46273)\n",
      "Traceback (most recent call last):\n",
      "  File \"/opt/conda/miniconda3/lib/python3.8/site-packages/IPython/core/interactiveshell.py\", line 3433, in run_code\n",
      "    exec(code_obj, self.user_global_ns, self.user_ns)\n",
      "  File \"/tmp/ipykernel_11737/4115056868.py\", line 1, in <module>\n",
      "    results.join(crypto_df,results.date ==  crypto_df.date,\"left\").show()\n",
      "  File \"/usr/lib/spark/python/pyspark/sql/dataframe.py\", line 484, in show\n",
      "    print(self._jdf.showString(n, 20, vertical))\n",
      "  File \"/usr/lib/spark/python/lib/py4j-0.10.9-src.zip/py4j/java_gateway.py\", line 1304, in __call__\n",
      "    return_value = get_return_value(\n",
      "  File \"/usr/lib/spark/python/pyspark/sql/utils.py\", line 111, in deco\n",
      "    return f(*a, **kw)\n",
      "  File \"/usr/lib/spark/python/lib/py4j-0.10.9-src.zip/py4j/protocol.py\", line 334, in get_return_value\n",
      "    raise Py4JError(\n",
      "py4j.protocol.Py4JError: An error occurred while calling o268.showString\n",
      "\n",
      "During handling of the above exception, another exception occurred:\n",
      "\n",
      "Traceback (most recent call last):\n",
      "  File \"/usr/lib/spark/python/lib/py4j-0.10.9-src.zip/py4j/java_gateway.py\", line 977, in _get_connection\n",
      "    connection = self.deque.pop()\n",
      "IndexError: pop from an empty deque\n",
      "\n",
      "During handling of the above exception, another exception occurred:\n",
      "\n",
      "Traceback (most recent call last):\n",
      "  File \"/usr/lib/spark/python/lib/py4j-0.10.9-src.zip/py4j/java_gateway.py\", line 1115, in start\n",
      "    self.socket.connect((self.address, self.port))\n",
      "ConnectionRefusedError: [Errno 111] Connection refused\n",
      "ERROR:py4j.java_gateway:An error occurred while trying to connect to the Java server (127.0.0.1:46273)\n",
      "Traceback (most recent call last):\n",
      "  File \"/opt/conda/miniconda3/lib/python3.8/site-packages/IPython/core/interactiveshell.py\", line 3433, in run_code\n",
      "    exec(code_obj, self.user_global_ns, self.user_ns)\n",
      "  File \"/tmp/ipykernel_11737/4115056868.py\", line 1, in <module>\n",
      "    results.join(crypto_df,results.date ==  crypto_df.date,\"left\").show()\n",
      "  File \"/usr/lib/spark/python/pyspark/sql/dataframe.py\", line 484, in show\n",
      "    print(self._jdf.showString(n, 20, vertical))\n",
      "  File \"/usr/lib/spark/python/lib/py4j-0.10.9-src.zip/py4j/java_gateway.py\", line 1304, in __call__\n",
      "    return_value = get_return_value(\n",
      "  File \"/usr/lib/spark/python/pyspark/sql/utils.py\", line 111, in deco\n",
      "    return f(*a, **kw)\n",
      "  File \"/usr/lib/spark/python/lib/py4j-0.10.9-src.zip/py4j/protocol.py\", line 334, in get_return_value\n",
      "    raise Py4JError(\n",
      "py4j.protocol.Py4JError: An error occurred while calling o268.showString\n",
      "\n",
      "During handling of the above exception, another exception occurred:\n",
      "\n",
      "Traceback (most recent call last):\n",
      "  File \"/usr/lib/spark/python/lib/py4j-0.10.9-src.zip/py4j/java_gateway.py\", line 977, in _get_connection\n",
      "    connection = self.deque.pop()\n",
      "IndexError: pop from an empty deque\n",
      "\n",
      "During handling of the above exception, another exception occurred:\n",
      "\n",
      "Traceback (most recent call last):\n",
      "  File \"/usr/lib/spark/python/lib/py4j-0.10.9-src.zip/py4j/java_gateway.py\", line 1115, in start\n",
      "    self.socket.connect((self.address, self.port))\n",
      "ConnectionRefusedError: [Errno 111] Connection refused\n",
      "ERROR:py4j.java_gateway:An error occurred while trying to connect to the Java server (127.0.0.1:46273)\n",
      "Traceback (most recent call last):\n",
      "  File \"/opt/conda/miniconda3/lib/python3.8/site-packages/IPython/core/interactiveshell.py\", line 3433, in run_code\n",
      "    exec(code_obj, self.user_global_ns, self.user_ns)\n",
      "  File \"/tmp/ipykernel_11737/4115056868.py\", line 1, in <module>\n",
      "    results.join(crypto_df,results.date ==  crypto_df.date,\"left\").show()\n",
      "  File \"/usr/lib/spark/python/pyspark/sql/dataframe.py\", line 484, in show\n",
      "    print(self._jdf.showString(n, 20, vertical))\n",
      "  File \"/usr/lib/spark/python/lib/py4j-0.10.9-src.zip/py4j/java_gateway.py\", line 1304, in __call__\n",
      "    return_value = get_return_value(\n",
      "  File \"/usr/lib/spark/python/pyspark/sql/utils.py\", line 111, in deco\n",
      "    return f(*a, **kw)\n",
      "  File \"/usr/lib/spark/python/lib/py4j-0.10.9-src.zip/py4j/protocol.py\", line 334, in get_return_value\n",
      "    raise Py4JError(\n",
      "py4j.protocol.Py4JError: An error occurred while calling o268.showString\n",
      "\n",
      "During handling of the above exception, another exception occurred:\n",
      "\n",
      "Traceback (most recent call last):\n",
      "  File \"/usr/lib/spark/python/lib/py4j-0.10.9-src.zip/py4j/java_gateway.py\", line 977, in _get_connection\n",
      "    connection = self.deque.pop()\n",
      "IndexError: pop from an empty deque\n",
      "\n",
      "During handling of the above exception, another exception occurred:\n",
      "\n",
      "Traceback (most recent call last):\n",
      "  File \"/usr/lib/spark/python/lib/py4j-0.10.9-src.zip/py4j/java_gateway.py\", line 1115, in start\n",
      "    self.socket.connect((self.address, self.port))\n",
      "ConnectionRefusedError: [Errno 111] Connection refused\n",
      "ERROR:py4j.java_gateway:An error occurred while trying to connect to the Java server (127.0.0.1:46273)\n",
      "Traceback (most recent call last):\n",
      "  File \"/opt/conda/miniconda3/lib/python3.8/site-packages/IPython/core/interactiveshell.py\", line 3433, in run_code\n",
      "    exec(code_obj, self.user_global_ns, self.user_ns)\n",
      "  File \"/tmp/ipykernel_11737/4115056868.py\", line 1, in <module>\n",
      "    results.join(crypto_df,results.date ==  crypto_df.date,\"left\").show()\n",
      "  File \"/usr/lib/spark/python/pyspark/sql/dataframe.py\", line 484, in show\n",
      "    print(self._jdf.showString(n, 20, vertical))\n",
      "  File \"/usr/lib/spark/python/lib/py4j-0.10.9-src.zip/py4j/java_gateway.py\", line 1304, in __call__\n",
      "    return_value = get_return_value(\n",
      "  File \"/usr/lib/spark/python/pyspark/sql/utils.py\", line 111, in deco\n",
      "    return f(*a, **kw)\n",
      "  File \"/usr/lib/spark/python/lib/py4j-0.10.9-src.zip/py4j/protocol.py\", line 334, in get_return_value\n",
      "    raise Py4JError(\n",
      "py4j.protocol.Py4JError: An error occurred while calling o268.showString\n",
      "\n",
      "During handling of the above exception, another exception occurred:\n",
      "\n",
      "Traceback (most recent call last):\n",
      "  File \"/usr/lib/spark/python/lib/py4j-0.10.9-src.zip/py4j/java_gateway.py\", line 977, in _get_connection\n",
      "    connection = self.deque.pop()\n",
      "IndexError: pop from an empty deque\n",
      "\n",
      "During handling of the above exception, another exception occurred:\n",
      "\n",
      "Traceback (most recent call last):\n",
      "  File \"/usr/lib/spark/python/lib/py4j-0.10.9-src.zip/py4j/java_gateway.py\", line 1115, in start\n",
      "    self.socket.connect((self.address, self.port))\n",
      "ConnectionRefusedError: [Errno 111] Connection refused\n"
     ]
    },
    {
     "name": "stderr",
     "output_type": "stream",
     "text": [
      "ERROR:py4j.java_gateway:An error occurred while trying to connect to the Java server (127.0.0.1:46273)\n",
      "Traceback (most recent call last):\n",
      "  File \"/opt/conda/miniconda3/lib/python3.8/site-packages/IPython/core/interactiveshell.py\", line 3433, in run_code\n",
      "    exec(code_obj, self.user_global_ns, self.user_ns)\n",
      "  File \"/tmp/ipykernel_11737/4115056868.py\", line 1, in <module>\n",
      "    results.join(crypto_df,results.date ==  crypto_df.date,\"left\").show()\n",
      "  File \"/usr/lib/spark/python/pyspark/sql/dataframe.py\", line 484, in show\n",
      "    print(self._jdf.showString(n, 20, vertical))\n",
      "  File \"/usr/lib/spark/python/lib/py4j-0.10.9-src.zip/py4j/java_gateway.py\", line 1304, in __call__\n",
      "    return_value = get_return_value(\n",
      "  File \"/usr/lib/spark/python/pyspark/sql/utils.py\", line 111, in deco\n",
      "    return f(*a, **kw)\n",
      "  File \"/usr/lib/spark/python/lib/py4j-0.10.9-src.zip/py4j/protocol.py\", line 334, in get_return_value\n",
      "    raise Py4JError(\n",
      "py4j.protocol.Py4JError: An error occurred while calling o268.showString\n",
      "\n",
      "During handling of the above exception, another exception occurred:\n",
      "\n",
      "Traceback (most recent call last):\n",
      "  File \"/usr/lib/spark/python/lib/py4j-0.10.9-src.zip/py4j/java_gateway.py\", line 977, in _get_connection\n",
      "    connection = self.deque.pop()\n",
      "IndexError: pop from an empty deque\n",
      "\n",
      "During handling of the above exception, another exception occurred:\n",
      "\n",
      "Traceback (most recent call last):\n",
      "  File \"/usr/lib/spark/python/lib/py4j-0.10.9-src.zip/py4j/java_gateway.py\", line 1115, in start\n",
      "    self.socket.connect((self.address, self.port))\n",
      "ConnectionRefusedError: [Errno 111] Connection refused\n",
      "ERROR:py4j.java_gateway:An error occurred while trying to connect to the Java server (127.0.0.1:46273)\n",
      "Traceback (most recent call last):\n",
      "  File \"/opt/conda/miniconda3/lib/python3.8/site-packages/IPython/core/interactiveshell.py\", line 3433, in run_code\n",
      "    exec(code_obj, self.user_global_ns, self.user_ns)\n",
      "  File \"/tmp/ipykernel_11737/4115056868.py\", line 1, in <module>\n",
      "    results.join(crypto_df,results.date ==  crypto_df.date,\"left\").show()\n",
      "  File \"/usr/lib/spark/python/pyspark/sql/dataframe.py\", line 484, in show\n",
      "    print(self._jdf.showString(n, 20, vertical))\n",
      "  File \"/usr/lib/spark/python/lib/py4j-0.10.9-src.zip/py4j/java_gateway.py\", line 1304, in __call__\n",
      "    return_value = get_return_value(\n",
      "  File \"/usr/lib/spark/python/pyspark/sql/utils.py\", line 111, in deco\n",
      "    return f(*a, **kw)\n",
      "  File \"/usr/lib/spark/python/lib/py4j-0.10.9-src.zip/py4j/protocol.py\", line 334, in get_return_value\n",
      "    raise Py4JError(\n",
      "py4j.protocol.Py4JError: An error occurred while calling o268.showString\n",
      "\n",
      "During handling of the above exception, another exception occurred:\n",
      "\n",
      "Traceback (most recent call last):\n",
      "  File \"/usr/lib/spark/python/lib/py4j-0.10.9-src.zip/py4j/java_gateway.py\", line 977, in _get_connection\n",
      "    connection = self.deque.pop()\n",
      "IndexError: pop from an empty deque\n",
      "\n",
      "During handling of the above exception, another exception occurred:\n",
      "\n",
      "Traceback (most recent call last):\n",
      "  File \"/usr/lib/spark/python/lib/py4j-0.10.9-src.zip/py4j/java_gateway.py\", line 1115, in start\n",
      "    self.socket.connect((self.address, self.port))\n",
      "ConnectionRefusedError: [Errno 111] Connection refused\n",
      "ERROR:py4j.java_gateway:An error occurred while trying to connect to the Java server (127.0.0.1:46273)\n",
      "Traceback (most recent call last):\n",
      "  File \"/opt/conda/miniconda3/lib/python3.8/site-packages/IPython/core/interactiveshell.py\", line 3433, in run_code\n",
      "    exec(code_obj, self.user_global_ns, self.user_ns)\n",
      "  File \"/tmp/ipykernel_11737/4115056868.py\", line 1, in <module>\n",
      "    results.join(crypto_df,results.date ==  crypto_df.date,\"left\").show()\n",
      "  File \"/usr/lib/spark/python/pyspark/sql/dataframe.py\", line 484, in show\n",
      "    print(self._jdf.showString(n, 20, vertical))\n",
      "  File \"/usr/lib/spark/python/lib/py4j-0.10.9-src.zip/py4j/java_gateway.py\", line 1304, in __call__\n",
      "    return_value = get_return_value(\n",
      "  File \"/usr/lib/spark/python/pyspark/sql/utils.py\", line 111, in deco\n",
      "    return f(*a, **kw)\n",
      "  File \"/usr/lib/spark/python/lib/py4j-0.10.9-src.zip/py4j/protocol.py\", line 334, in get_return_value\n",
      "    raise Py4JError(\n",
      "py4j.protocol.Py4JError: An error occurred while calling o268.showString\n",
      "\n",
      "During handling of the above exception, another exception occurred:\n",
      "\n",
      "Traceback (most recent call last):\n",
      "  File \"/usr/lib/spark/python/lib/py4j-0.10.9-src.zip/py4j/java_gateway.py\", line 977, in _get_connection\n",
      "    connection = self.deque.pop()\n",
      "IndexError: pop from an empty deque\n",
      "\n",
      "During handling of the above exception, another exception occurred:\n",
      "\n",
      "Traceback (most recent call last):\n",
      "  File \"/usr/lib/spark/python/lib/py4j-0.10.9-src.zip/py4j/java_gateway.py\", line 1115, in start\n",
      "    self.socket.connect((self.address, self.port))\n",
      "ConnectionRefusedError: [Errno 111] Connection refused\n",
      "ERROR:py4j.java_gateway:An error occurred while trying to connect to the Java server (127.0.0.1:46273)\n",
      "Traceback (most recent call last):\n",
      "  File \"/opt/conda/miniconda3/lib/python3.8/site-packages/IPython/core/interactiveshell.py\", line 3433, in run_code\n",
      "    exec(code_obj, self.user_global_ns, self.user_ns)\n",
      "  File \"/tmp/ipykernel_11737/4115056868.py\", line 1, in <module>\n",
      "    results.join(crypto_df,results.date ==  crypto_df.date,\"left\").show()\n",
      "  File \"/usr/lib/spark/python/pyspark/sql/dataframe.py\", line 484, in show\n",
      "    print(self._jdf.showString(n, 20, vertical))\n",
      "  File \"/usr/lib/spark/python/lib/py4j-0.10.9-src.zip/py4j/java_gateway.py\", line 1304, in __call__\n",
      "    return_value = get_return_value(\n",
      "  File \"/usr/lib/spark/python/pyspark/sql/utils.py\", line 111, in deco\n",
      "    return f(*a, **kw)\n",
      "  File \"/usr/lib/spark/python/lib/py4j-0.10.9-src.zip/py4j/protocol.py\", line 334, in get_return_value\n",
      "    raise Py4JError(\n",
      "py4j.protocol.Py4JError: An error occurred while calling o268.showString\n",
      "\n",
      "During handling of the above exception, another exception occurred:\n",
      "\n",
      "Traceback (most recent call last):\n",
      "  File \"/usr/lib/spark/python/lib/py4j-0.10.9-src.zip/py4j/java_gateway.py\", line 977, in _get_connection\n",
      "    connection = self.deque.pop()\n",
      "IndexError: pop from an empty deque\n",
      "\n",
      "During handling of the above exception, another exception occurred:\n",
      "\n",
      "Traceback (most recent call last):\n",
      "  File \"/usr/lib/spark/python/lib/py4j-0.10.9-src.zip/py4j/java_gateway.py\", line 1115, in start\n",
      "    self.socket.connect((self.address, self.port))\n",
      "ConnectionRefusedError: [Errno 111] Connection refused\n"
     ]
    },
    {
     "ename": "Py4JError",
     "evalue": "An error occurred while calling o268.showString",
     "output_type": "error",
     "traceback": [
      "\u001b[0;31m---------------------------------------------------------------------------\u001b[0m",
      "\u001b[0;31mPy4JError\u001b[0m                                 Traceback (most recent call last)",
      "Cell \u001b[0;32mIn[12], line 1\u001b[0m\n\u001b[0;32m----> 1\u001b[0m \u001b[43mresults\u001b[49m\u001b[38;5;241;43m.\u001b[39;49m\u001b[43mjoin\u001b[49m\u001b[43m(\u001b[49m\u001b[43mcrypto_df\u001b[49m\u001b[43m,\u001b[49m\u001b[43mresults\u001b[49m\u001b[38;5;241;43m.\u001b[39;49m\u001b[43mdate\u001b[49m\u001b[43m \u001b[49m\u001b[38;5;241;43m==\u001b[39;49m\u001b[43m  \u001b[49m\u001b[43mcrypto_df\u001b[49m\u001b[38;5;241;43m.\u001b[39;49m\u001b[43mdate\u001b[49m\u001b[43m,\u001b[49m\u001b[38;5;124;43m\"\u001b[39;49m\u001b[38;5;124;43mleft\u001b[39;49m\u001b[38;5;124;43m\"\u001b[39;49m\u001b[43m)\u001b[49m\u001b[38;5;241;43m.\u001b[39;49m\u001b[43mshow\u001b[49m\u001b[43m(\u001b[49m\u001b[43m)\u001b[49m\n",
      "File \u001b[0;32m/usr/lib/spark/python/pyspark/sql/dataframe.py:484\u001b[0m, in \u001b[0;36mDataFrame.show\u001b[0;34m(self, n, truncate, vertical)\u001b[0m\n\u001b[1;32m    441\u001b[0m \u001b[38;5;124;03m\"\"\"Prints the first ``n`` rows to the console.\u001b[39;00m\n\u001b[1;32m    442\u001b[0m \n\u001b[1;32m    443\u001b[0m \u001b[38;5;124;03m.. versionadded:: 1.3.0\u001b[39;00m\n\u001b[0;32m   (...)\u001b[0m\n\u001b[1;32m    481\u001b[0m \u001b[38;5;124;03m name | Bob\u001b[39;00m\n\u001b[1;32m    482\u001b[0m \u001b[38;5;124;03m\"\"\"\u001b[39;00m\n\u001b[1;32m    483\u001b[0m \u001b[38;5;28;01mif\u001b[39;00m \u001b[38;5;28misinstance\u001b[39m(truncate, \u001b[38;5;28mbool\u001b[39m) \u001b[38;5;129;01mand\u001b[39;00m truncate:\n\u001b[0;32m--> 484\u001b[0m     \u001b[38;5;28mprint\u001b[39m(\u001b[38;5;28;43mself\u001b[39;49m\u001b[38;5;241;43m.\u001b[39;49m\u001b[43m_jdf\u001b[49m\u001b[38;5;241;43m.\u001b[39;49m\u001b[43mshowString\u001b[49m\u001b[43m(\u001b[49m\u001b[43mn\u001b[49m\u001b[43m,\u001b[49m\u001b[43m \u001b[49m\u001b[38;5;241;43m20\u001b[39;49m\u001b[43m,\u001b[49m\u001b[43m \u001b[49m\u001b[43mvertical\u001b[49m\u001b[43m)\u001b[49m)\n\u001b[1;32m    485\u001b[0m \u001b[38;5;28;01melse\u001b[39;00m:\n\u001b[1;32m    486\u001b[0m     \u001b[38;5;28mprint\u001b[39m(\u001b[38;5;28mself\u001b[39m\u001b[38;5;241m.\u001b[39m_jdf\u001b[38;5;241m.\u001b[39mshowString(n, \u001b[38;5;28mint\u001b[39m(truncate), vertical))\n",
      "File \u001b[0;32m/usr/lib/spark/python/lib/py4j-0.10.9-src.zip/py4j/java_gateway.py:1304\u001b[0m, in \u001b[0;36mJavaMember.__call__\u001b[0;34m(self, *args)\u001b[0m\n\u001b[1;32m   1298\u001b[0m command \u001b[38;5;241m=\u001b[39m proto\u001b[38;5;241m.\u001b[39mCALL_COMMAND_NAME \u001b[38;5;241m+\u001b[39m\\\n\u001b[1;32m   1299\u001b[0m     \u001b[38;5;28mself\u001b[39m\u001b[38;5;241m.\u001b[39mcommand_header \u001b[38;5;241m+\u001b[39m\\\n\u001b[1;32m   1300\u001b[0m     args_command \u001b[38;5;241m+\u001b[39m\\\n\u001b[1;32m   1301\u001b[0m     proto\u001b[38;5;241m.\u001b[39mEND_COMMAND_PART\n\u001b[1;32m   1303\u001b[0m answer \u001b[38;5;241m=\u001b[39m \u001b[38;5;28mself\u001b[39m\u001b[38;5;241m.\u001b[39mgateway_client\u001b[38;5;241m.\u001b[39msend_command(command)\n\u001b[0;32m-> 1304\u001b[0m return_value \u001b[38;5;241m=\u001b[39m \u001b[43mget_return_value\u001b[49m\u001b[43m(\u001b[49m\n\u001b[1;32m   1305\u001b[0m \u001b[43m    \u001b[49m\u001b[43manswer\u001b[49m\u001b[43m,\u001b[49m\u001b[43m \u001b[49m\u001b[38;5;28;43mself\u001b[39;49m\u001b[38;5;241;43m.\u001b[39;49m\u001b[43mgateway_client\u001b[49m\u001b[43m,\u001b[49m\u001b[43m \u001b[49m\u001b[38;5;28;43mself\u001b[39;49m\u001b[38;5;241;43m.\u001b[39;49m\u001b[43mtarget_id\u001b[49m\u001b[43m,\u001b[49m\u001b[43m \u001b[49m\u001b[38;5;28;43mself\u001b[39;49m\u001b[38;5;241;43m.\u001b[39;49m\u001b[43mname\u001b[49m\u001b[43m)\u001b[49m\n\u001b[1;32m   1307\u001b[0m \u001b[38;5;28;01mfor\u001b[39;00m temp_arg \u001b[38;5;129;01min\u001b[39;00m temp_args:\n\u001b[1;32m   1308\u001b[0m     temp_arg\u001b[38;5;241m.\u001b[39m_detach()\n",
      "File \u001b[0;32m/usr/lib/spark/python/pyspark/sql/utils.py:111\u001b[0m, in \u001b[0;36mcapture_sql_exception.<locals>.deco\u001b[0;34m(*a, **kw)\u001b[0m\n\u001b[1;32m    109\u001b[0m \u001b[38;5;28;01mdef\u001b[39;00m \u001b[38;5;21mdeco\u001b[39m(\u001b[38;5;241m*\u001b[39ma, \u001b[38;5;241m*\u001b[39m\u001b[38;5;241m*\u001b[39mkw):\n\u001b[1;32m    110\u001b[0m     \u001b[38;5;28;01mtry\u001b[39;00m:\n\u001b[0;32m--> 111\u001b[0m         \u001b[38;5;28;01mreturn\u001b[39;00m \u001b[43mf\u001b[49m\u001b[43m(\u001b[49m\u001b[38;5;241;43m*\u001b[39;49m\u001b[43ma\u001b[49m\u001b[43m,\u001b[49m\u001b[43m \u001b[49m\u001b[38;5;241;43m*\u001b[39;49m\u001b[38;5;241;43m*\u001b[39;49m\u001b[43mkw\u001b[49m\u001b[43m)\u001b[49m\n\u001b[1;32m    112\u001b[0m     \u001b[38;5;28;01mexcept\u001b[39;00m py4j\u001b[38;5;241m.\u001b[39mprotocol\u001b[38;5;241m.\u001b[39mPy4JJavaError \u001b[38;5;28;01mas\u001b[39;00m e:\n\u001b[1;32m    113\u001b[0m         converted \u001b[38;5;241m=\u001b[39m convert_exception(e\u001b[38;5;241m.\u001b[39mjava_exception)\n",
      "File \u001b[0;32m/usr/lib/spark/python/lib/py4j-0.10.9-src.zip/py4j/protocol.py:334\u001b[0m, in \u001b[0;36mget_return_value\u001b[0;34m(answer, gateway_client, target_id, name)\u001b[0m\n\u001b[1;32m    330\u001b[0m             \u001b[38;5;28;01mraise\u001b[39;00m Py4JError(\n\u001b[1;32m    331\u001b[0m                 \u001b[38;5;124m\"\u001b[39m\u001b[38;5;124mAn error occurred while calling \u001b[39m\u001b[38;5;132;01m{0}\u001b[39;00m\u001b[38;5;132;01m{1}\u001b[39;00m\u001b[38;5;132;01m{2}\u001b[39;00m\u001b[38;5;124m. Trace:\u001b[39m\u001b[38;5;130;01m\\n\u001b[39;00m\u001b[38;5;132;01m{3}\u001b[39;00m\u001b[38;5;130;01m\\n\u001b[39;00m\u001b[38;5;124m\"\u001b[39m\u001b[38;5;241m.\u001b[39m\n\u001b[1;32m    332\u001b[0m                 \u001b[38;5;28mformat\u001b[39m(target_id, \u001b[38;5;124m\"\u001b[39m\u001b[38;5;124m.\u001b[39m\u001b[38;5;124m\"\u001b[39m, name, value))\n\u001b[1;32m    333\u001b[0m     \u001b[38;5;28;01melse\u001b[39;00m:\n\u001b[0;32m--> 334\u001b[0m         \u001b[38;5;28;01mraise\u001b[39;00m Py4JError(\n\u001b[1;32m    335\u001b[0m             \u001b[38;5;124m\"\u001b[39m\u001b[38;5;124mAn error occurred while calling \u001b[39m\u001b[38;5;132;01m{0}\u001b[39;00m\u001b[38;5;132;01m{1}\u001b[39;00m\u001b[38;5;132;01m{2}\u001b[39;00m\u001b[38;5;124m\"\u001b[39m\u001b[38;5;241m.\u001b[39m\n\u001b[1;32m    336\u001b[0m             \u001b[38;5;28mformat\u001b[39m(target_id, \u001b[38;5;124m\"\u001b[39m\u001b[38;5;124m.\u001b[39m\u001b[38;5;124m\"\u001b[39m, name))\n\u001b[1;32m    337\u001b[0m \u001b[38;5;28;01melse\u001b[39;00m:\n\u001b[1;32m    338\u001b[0m     \u001b[38;5;28mtype\u001b[39m \u001b[38;5;241m=\u001b[39m answer[\u001b[38;5;241m1\u001b[39m]\n",
      "\u001b[0;31mPy4JError\u001b[0m: An error occurred while calling o268.showString"
     ]
    }
   ],
   "source": [
    "results.join(crypto_df,results.date ==  crypto_df.date,\"left\").show()"
   ]
  },
  {
   "cell_type": "code",
   "execution_count": null,
   "id": "3d13ee56",
   "metadata": {},
   "outputs": [],
   "source": [
    "# cmd = f'hdfs dfs -rmr {results_path}'\n",
    "# os.system(cmd)\n",
    "# test_df.write.csv(results, header=True)"
   ]
  }
 ],
 "metadata": {
  "kernelspec": {
   "display_name": "PySpark",
   "language": "python",
   "name": "pyspark"
  },
  "language_info": {
   "codemirror_mode": {
    "name": "ipython",
    "version": 3
   },
   "file_extension": ".py",
   "mimetype": "text/x-python",
   "name": "python",
   "nbconvert_exporter": "python",
   "pygments_lexer": "ipython3",
   "version": "3.8.15"
  }
 },
 "nbformat": 4,
 "nbformat_minor": 5
}
